Workbook

Sheet הנחיות
A1: פרופיל אורייני — מיפוי כיתתי ובית-ספרי
A2: חינוך מיוחד | שני מסלולי מיפוי · קריאה, שפה בעל פה וכתיבה · מבנה מצטבר
A4: עיקרון המבנה
A5: מבנה מצטבר | B5: שורה לכל תלמיד בכל פעימה, בכל שנה. אין לדרוס שורות קודמות — פעימה חדשה נרשמת בשורה חדשה. כך נשמרת ההתקדמות ואפשר לראות תנועה לאורך השנה ולאורך השנים.
A7: שני המסלולים
A8: שלב הרכישה | B8: תלמידים שטרם השלימו את רכישת יסודות הקריאה. גיליון 'הזנה רכישה', חמישה פרופילים (1 הגבוה — 5 הנמוך).
A9: רמת ב'-ו' | B9: תלמידים שביססו את יסודות הקריאה ומפענחים. גיליון 'הזנה ב-ו', חמש קטגוריות הפרופיל האורייני.
A10: נוהל הירידה | B10: תלמיד שאינו מוכר — מתחילים בכתב מנוקד ברמת טקסט משוערת. קורא ברהיטות — עולים לכתב לא מנוקד. מתקשה בכתב מנוקד — עוצרים, יורדים רמת טקסט ובודקים שוב, עד למציאת הרמה שבה הוא מתפקד. תלמיד שאינו מתפקד גם ברמת כיתה ב' — שייך למסלול הרכישה.
A11: רמת הטקסט | B11: תוצאה של נוהל הירידה, ולא הערכה מוקדמת. היא אינה משפיעה על חישוב הפרופיל, אך בלעדיה אי אפשר לראות התקדמות: תלמיד יכול להישאר באותו פרופיל ולעלות רמת טקסט — וזו התקדמות אמיתית.
A13: סדר העבודה
A14: 1 | B14: המורה מזינה את הנתונים באפליקציית מבדקי קריאה (המקור), בזמן ההעברה. אין צורך להקליד בקובץ הזה.
A15: 2 | B15: ההזנה האחרונה של כל תלמיד בכל פעימה מועתקת אוטומטית מהמקור אל גיליונות ההזנה, כולל שנת לימודים ופעימה.
A16: 3 | B16: בגיליון 'דף הכיתה' בוחרים כיתה, שנה ופעימה ומקבלים את קבוצות ההוראה ואת התנועה מהפעימה הקודמת. דף זה מיועד להדפסה.
A17: 4 | B17: בגיליון 'כרטיס תלמיד' בוחרים שם ורואים את כל הפעימות של אותו תלמיד לאורך השנים.
A18: 5 | B18: גיליון 'מבט בית-ספרי' מרכז את שני המסלולים ומשווה בין הפעימות. אינו דורש מילוי.
A20: הפעימות
A21: קריאה | B21: שלוש פעימות: תחילת שנה · מחצית שנה · סוף השנה.
A22: כתיבה | B22: שתי פעימות בלבד, בשדה נפרד. ניתן לסמן 'טרם נבדק' בפעימה שבה לא נבדקה כתיבה.
A24: צבעי התאים
A25: תכלת | B25: תא שמתמלא אוטומטית, מהמקור או בחישוב. אין לכתוב בו.
A26: מזהה תלמיד | B26: כיתה ומספר תלמיד, למשל ח'1/ 5. אין שמות תלמידים בקובץ.
A28: שכבת הכתיבה — רמת ב'-ו'
A29: שני אשכולות | B29: כתיבה (מערכת הרישום): כתב · כתיב. | הבעה בכתב (שיח כתוב): תוכן · ארגון ולכידות · לשון.
A30: מדוע ההפרדה | B30: הבעה בכתב מתפתחת מהשיח הדבור, הרבה לפני שהתלמיד שולט במיומנויות הכתיבה הטכניות. תלמיד עם כתיב חלש והבעה מפותחת אינו 'כתיבתו אינה מפותחת'.
A31: ההשפעה על הפרופיל | B31: רק אשכול ההבעה בכתב משפיע על השיוך. הכתב והכתיב נאספים ומתועדים אך אינם משנים את הפרופיל.
A32: הבעה בכתב | B32: 'מפותחת' — שלושת הרכיבים ברמה העליונה. | 'אינה מפותחת' — שניים לפחות ברמה הנמוכה. | אחרת — 'חלקית'.
A33: הסוגה | B33: סיפורי · מידעי · רפלקטיבי. יש לגוון לאורך השנה — תלמיד עשוי להצליח בסוגה אחת ולהתקשות באחרת.
A35: כללי החישוב — רמת ב'-ו'
A36: איכות הקריאה | B36: 'רהוטה' — דיוק, קצב ופרוזודיה תקינים. | 'מדויקת ורציפה' — דיוק וקצב תקינים. | אחרת — 'אינה מדויקת או מקוטעת'.
A37: חולשה שפתית | B37: 'ניכרת' כאשר הבנת הנשמע נמוכה, או כאשר שניים לפחות מתוך שלושה — הבנת הנשמע, אוצר מילים, יכולת הבעה — אינם תקינים.
A38: הרמה | B38: רמה א' — מיקוד בשטף / בשטף ובכישורי שפה. | רמה ב' — מיקוד בכישורי שפה / בהבנה והבעה. | רמה ג' — קוראים וכותבים מיומנים: קריאה רהוטה או מדויקת ורציפה, בלי חולשה שפתית, הבנת הנקרא תקינה והבעה בכתב מפותחת. הנגנה אינה מעכבת, ואם אינה תקינה נרשם בהערה: נדרש לעבוד על ההנגנה.
A39: נתונים נדרשים | B39: לשיוך נדרשים כל הנתונים: שטף (דיוק, קצב, פרוזודיה), הבנת הנקרא, הבנת הנשמע, אוצר מילים, יכולת הבעה וכתיבה. חסר נתון: "טרם שויך".
A40: כללי החישוב — שלב הרכישה
A41: המדד המכריע | B41: מספר סימני הניקוד: טרם מפענח — פרופיל 5 | קמץ/פתח/חטף-פתח ושוואים — פרופיל 4 | 2-3 סימנים — פרופיל 3 | 4-5 סימנים — פרופיל 2 | כל הסימנים — פרופיל 1 או 2.
A42: ההבחנה 1 מול 2 | B42: תלמיד המפענח בכל הסימנים ישויך לפרופיל 1 רק אם הוא מפיק בכתב משפטים וקטעים קצרים ומבין את הנקרא.
A43: קבוצות ההוראה | B43: קבוצת תשתיות — פרופיל 5. | קבוצת רכישה — פרופילים 4-3. | קבוצת ביסוס — פרופילים 2-1.

Sheet הזנה ב-ו
A1: גיליון הזנה — תפקוד אורייני ברמת כיתות ב'-ו'
A2: שורה לכל תלמיד בכל פעימה. אין לדרוס שורות קודמות — פעימה חדשה נרשמת בשורה חדשה, וכך נשמרת ההתקדמות.
A3: הגיליון מתמלא אוטומטית מהמקור. אין להקליד בו. העמודות התכולות הן העתקה מהמקור וחישוב.
A4: זיהוי | G4: קריאה והבנה | N4: שפה בעל פה | Q4: כתיבה | Y4: מחושב
A5: שנת לימודים | B5: כיתה | C5: תלמיד (כיתה/מספר) | D5: מורה | E5: תאריך | F5: פעימת קריאה | G5: רמת הטקסט | H5: רמת הכתב | I5: דיוק | J5: קצב | K5: פרוזודיה | L5: הבנת הנקרא | M5: הבנת הנשמע | N5: אוצר מילים | O5: יכולת הבעה | P5: השתתפות בשיח | Q5: פעימת כתיבה | R5: הסוגה שנבדקה | S5: כתב | T5: כתיב | U5: תוכן | V5: ארגון ולכידות | W5: לשון | X5: עמדה כלפי כתיבה | Y5: איכות הקריאה | Z5: הבעה בכתב | AA5: חולשה שפתית | AB5: הפרופיל (מחושב) | AC5: הרמה | AD5: הערה לקבוצה | AE5: סדר פעימה | AF5: מפתח קבוצה | AG5: מפתח תלמיד | AH5: מפתח קודם | AI5: הרמה הקודמת | AJ5: תנועה | AK5: היבטים רגשיים והתנהגותיים
Y6: =IF($C6="","",IF(COUNTA($I6:$K6)<3,"— חסרים נתונים",IF(AND($I6="תקין",$J6="תקין",$K6="תקין"),"רהוטה",IF(AND($I6="תקין",$J6="תקין"),"מדויקת ורציפה","אינה מדויקת או מקוטעת")))) | Z6: =IF($C6="","",IF(COUNTA($U6:$W6)<3,"",IF(AND($U6="מפותח",$V6="מפותח",$W6="מפותחת"),"מפותחת",IF((--($U6="דל"))+(--($V6="אינו מפותח"))+(--($W6="דלה"))>=2,"אינה מפותחת","חלקית")))) | AA6: =IF($C6="","",IF(COUNTA($M6,$N6,$O6)<3,"— חסרים נתונים",IF(OR($M6="נמוכה",(--($M6<>"תקינה"))+(--($N6<>"תקין"))+(--($O6<>"תקינה"))>=2),"ניכרת","אינה ניכרת"))) | AB6: =IF(OR($C6="",$Y6="",$AA6="",LEFT($Y6,1)="—",LEFT($AA6,1)="—"),"",IF($Z6="","— נדרשת הערכת כתיבה",IF($L6="","— חסרה הבנת הנקרא",IF($Y6="אינה מדויקת או מקוטעת",IF($AA6="ניכרת","מיקוד בשטף הקריאה ובכישורי שפה","מיקוד בשטף קריאה"),IF($AA6="ניכרת","מיקוד בכישורי שפה",IF(AND($L6="תקינה",$Z6="מפותחת"),"קוראים וכותבים מיומנים","מיקוד בהבנה והבעה")))))) | AC6: =IF(OR($AB6="",LEFT($AB6,1)="—"),"",IF(OR($AB6="מיקוד בשטף קריאה",$AB6="מיקוד בשטף הקריאה ובכישורי שפה"),"רמה א'",IF($AB6="קוראים וכותבים מיומנים","רמה ג'","רמה ב'"))) | AD6: =IF($AC6="","",MID(IF(AND($AC6="רמה א'",$AA6="ניכרת"),"; להוסיף עבודת אוצר מילים","")&IF($Z6="אינה מפותחת","; דגש על הבעה בכתב","")&IF($K6<>"תקין","; נדרש לעבוד על ההנגנה","")&IF($AK6<>"","; "&$AK6,""),3,400)) | AE6: =IF($F6="","",IF($F6="תחילת שנה",1,IF($F6="מחצית שנה",2,3))) | AF6: =IF(OR($B6="",$AC6="",$A6="",$F6=""),"",$B6&"|"&$A6&"|"&$F6&"|"&$AC6&"|"&COUNTIFS($B$6:$B6,$B6,$A$6:$A6,$A6,$F$6:$F6,$F6,$AC$6:$AC6,$AC6)) | AG6: =IF($C6="","",$C6&"|"&COUNTIFS($C$6:$C6,$C6)) | AH6: =IF(OR($C6="",$A6="",$AE6=""),"",$C6&"|"&$A6&"|"&$AE6) | AI6: =IF(OR($C6="",$AE6="",$AE6=1),"",IFERROR(INDEX($AC$6:$AC$1505,MATCH($C6&"|"&$A6&"|"&($AE6-1),$AH$6:$AH$1505,0)),"")) | AJ6: =IF(OR($AI6="",$AC6=""),"",IF($AI6=$AC6,"ללא שינוי","מ-"&$AI6&" ל-"&$AC6))
Y7: =IF($C7="","",IF(COUNTA($I7:$K7)<3,"— חסרים נתונים",IF(AND($I7="תקין",$J7="תקין",$K7="תקין"),"רהוטה",IF(AND($I7="תקין",$J7="תקין"),"מדויקת ורציפה","אינה מדויקת או מקוטעת")))) | Z7: =IF($C7="","",IF(COUNTA($U7:$W7)<3,"",IF(AND($U7="מפותח",$V7="מפותח",$W7="מפותחת"),"מפותחת",IF((--($U7="דל"))+(--($V7="אינו מפותח"))+(--($W7="דלה"))>=2,"אינה מפותחת","חלקית")))) | AA7: =IF($C7="","",IF(COUNTA($M7,$N7,$O7)<3,"— חסרים נתונים",IF(OR($M7="נמוכה",(--($M7<>"תקינה"))+(--($N7<>"תקין"))+(--($O7<>"תקינה"))>=2),"ניכרת","אינה ניכרת"))) | AB7: =IF(OR($C7="",$Y7="",$AA7="",LEFT($Y7,1)="—",LEFT($AA7,1)="—"),"",IF($Z7="","— נדרשת הערכת כתיבה",IF($L7="","— חסרה הבנת הנקרא",IF($Y7="אינה מדויקת או מקוטעת",IF($AA7="ניכרת","מיקוד בשטף הקריאה ובכישורי שפה","מיקוד בשטף קריאה"),IF($AA7="ניכרת","מיקוד בכישורי שפה",IF(AND($L7="תקינה",$Z7="מפותחת"),"קוראים וכותבים מיומנים","מיקוד בהבנה והבעה")))))) | AC7: =IF(OR($AB7="",LEFT($AB7,1)="—"),"",IF(OR($AB7="מיקוד בשטף קריאה",$AB7="מיקוד בשטף הקריאה ובכישורי שפה"),"רמה א'",IF($AB7="קוראים וכותבים מיומנים","רמה ג'","רמה ב'"))) | AD7: =IF($AC7="","",MID(IF(AND($AC7="רמה א'",$AA7="ניכרת"),"; להוסיף עבודת אוצר מילים","")&IF($Z7="אינה מפותחת","; דגש על הבעה בכתב","")&IF($K7<>"תקין","; נדרש לעבוד על ההנגנה","")&IF($AK7<>"","; "&$AK7,""),3,400)) | AE7: =IF($F7="","",IF($F7="תחילת שנה",1,IF($F7="מחצית שנה",2,3))) | AF7: =IF(OR($B7="",$AC7="",$A7="",$F7=""),"",$B7&"|"&$A7&"|"&$F7&"|"&$AC7&"|"&COUNTIFS($B$6:$B7,$B7,$A$6:$A7,$A7,$F$6:$F7,$F7,$AC$6:$AC7,$AC7)) | AG7: =IF($C7="","",$C7&"|"&COUNTIFS($C$6:$C7,$C7)) | AH7: =IF(OR($C7="",$A7="",$AE7=""),"",$C7&"|"&$A7&"|"&$AE7) | AI7: =IF(OR($C7="",$AE7="",$AE7=1),"",IFERROR(INDEX($AC$6:$AC$1505,MATCH($C7&"|"&$A7&"|"&($AE7-1),$AH$6:$AH$1505,0)),"")) | AJ7: =IF(OR($AI7="",$AC7=""),"",IF($AI7=$AC7,"ללא שינוי","מ-"&$AI7&" ל-"&$AC7))
Y8: =IF($C8="","",IF(COUNTA($I8:$K8)<3,"— חסרים נתונים",IF(AND($I8="תקין",$J8="תקין",$K8="תקין"),"רהוטה",IF(AND($I8="תקין",$J8="תקין"),"מדויקת ורציפה","אינה מדויקת או מקוטעת")))) | Z8: =IF($C8="","",IF(COUNTA($U8:$W8)<3,"",IF(AND($U8="מפותח",$V8="מפותח",$W8="מפותחת"),"מפותחת",IF((--($U8="דל"))+(--($V8="אינו מפותח"))+(--($W8="דלה"))>=2,"אינה מפותחת","חלקית")))) | AA8: =IF($C8="","",IF(COUNTA($M8,$N8,$O8)<3,"— חסרים נתונים",IF(OR($M8="נמוכה",(--($M8<>"תקינה"))+(--($N8<>"תקין"))+(--($O8<>"תקינה"))>=2),"ניכרת","אינה ניכרת"))) | AB8: =IF(OR($C8="",$Y8="",$AA8="",LEFT($Y8,1)="—",LEFT($AA8,1)="—"),"",IF($Z8="","— נדרשת הערכת כתיבה",IF($L8="","— חסרה הבנת הנקרא",IF($Y8="אינה מדויקת או מקוטעת",IF($AA8="ניכרת","מיקוד בשטף הקריאה ובכישורי שפה","מיקוד בשטף קריאה"),IF($AA8="ניכרת","מיקוד בכישורי שפה",IF(AND($L8="תקינה",$Z8="מפותחת"),"קוראים וכותבים מיומנים","מיקוד בהבנה והבעה")))))) | AC8: =IF(OR($AB8="",LEFT($AB8,1)="—"),"",IF(OR($AB8="מיקוד בשטף קריאה",$AB8="מיקוד בשטף הקריאה ובכישורי שפה"),"רמה א'",IF($AB8="קוראים וכותבים מיומנים","רמה ג'","רמה ב'"))) | AD8: =IF($AC8="","",MID(IF(AND($AC8="רמה א'",$AA8="ניכרת"),"; להוסיף עבודת אוצר מילים","")&IF($Z8="אינה מפותחת","; דגש על הבעה בכתב","")&IF($K8<>"תקין","; נדרש לעבוד על ההנגנה","")&IF($AK8<>"","; "&$AK8,""),3,400)) | AE8: =IF($F8="","",IF($F8="תחילת שנה",1,IF($F8="מחצית שנה",2,3))) | AF8: =IF(OR($B8="",$AC8="",$A8="",$F8=""),"",$B8&"|"&$A8&"|"&$F8&"|"&$AC8&"|"&COUNTIFS($B$6:$B8,$B8,$A$6:$A8,$A8,$F$6:$F8,$F8,$AC$6:$AC8,$AC8)) | AG8: =IF($C8="","",$C8&"|"&COUNTIFS($C$6:$C8,$C8)) | AH8: =IF(OR($C8="",$A8="",$AE8=""),"",$C8&"|"&$A8&"|"&$AE8) | AI8: =IF(OR($C8="",$AE8="",$AE8=1),"",IFERROR(INDEX($AC$6:$AC$1505,MATCH($C8&"|"&$A8&"|"&($AE8-1),$AH$6:$AH$1505,0)),"")) | AJ8: =IF(OR($AI8="",$AC8=""),"",IF($AI8=$AC8,"ללא שינוי","מ-"&$AI8&" ל-"&$AC8))
Y9: =IF($C9="","",IF(COUNTA($I9:$K9)<3,"— חסרים נתונים",IF(AND($I9="תקין",$J9="תקין",$K9="תקין"),"רהוטה",IF(AND($I9="תקין",$J9="תקין"),"מדויקת ורציפה","אינה מדויקת או מקוטעת")))) | Z9: =IF($C9="","",IF(COUNTA($U9:$W9)<3,"",IF(AND($U9="מפותח",$V9="מפותח",$W9="מפותחת"),"מפותחת",IF((--($U9="דל"))+(--($V9="אינו מפותח"))+(--($W9="דלה"))>=2,"אינה מפותחת","חלקית")))) | AA9: =IF($C9="","",IF(COUNTA($M9,$N9,$O9)<3,"— חסרים נתונים",IF(OR($M9="נמוכה",(--($M9<>"תקינה"))+(--($N9<>"תקין"))+(--($O9<>"תקינה"))>=2),"ניכרת","אינה ניכרת"))) | AB9: =IF(OR($C9="",$Y9="",$AA9="",LEFT($Y9,1)="—",LEFT($AA9,1)="—"),"",IF($Z9="","— נדרשת הערכת כתיבה",IF($L9="","— חסרה הבנת הנקרא",IF($Y9="אינה מדויקת או מקוטעת",IF($AA9="ניכרת","מיקוד בשטף הקריאה ובכישורי שפה","מיקוד בשטף קריאה"),IF($AA9="ניכרת","מיקוד בכישורי שפה",IF(AND($L9="תקינה",$Z9="מפותחת"),"קוראים וכותבים מיומנים","מיקוד בהבנה והבעה")))))) | AC9: =IF(OR($AB9="",LEFT($AB9,1)="—"),"",IF(OR($AB9="מיקוד בשטף קריאה",$AB9="מיקוד בשטף הקריאה ובכישורי שפה"),"רמה א'",IF($AB9="קוראים וכותבים מיומנים","רמה ג'","רמה ב'"))) | AD9: =IF($AC9="","",MID(IF(AND($AC9="רמה א'",$AA9="ניכרת"),"; להוסיף עבודת אוצר מילים","")&IF($Z9="אינה מפותחת","; דגש על הבעה בכתב","")&IF($K9<>"תקין","; נדרש לעבוד על ההנגנה","")&IF($AK9<>"","; "&$AK9,""),3,400)) | AE9: =IF($F9="","",IF($F9="תחילת שנה",1,IF($F9="מחצית שנה",2,3))) | AF9: =IF(OR($B9="",$AC9="",$A9="",$F9=""),"",$B9&"|"&$A9&"|"&$F9&"|"&$AC9&"|"&COUNTIFS($B$6:$B9,$B9,$A$6:$A9,$A9,$F$6:$F9,$F9,$AC$6:$AC9,$AC9)) | AG9: =IF($C9="","",$C9&"|"&COUNTIFS($C$6:$C9,$C9)) | AH9: =IF(OR($C9="",$A9="",$AE9=""),"",$C9&"|"&$A9&"|"&$AE9) | AI9: =IF(OR($C9="",$AE9="",$AE9=1),"",IFERROR(INDEX($AC$6:$AC$1505,MATCH($C9&"|"&$A9&"|"&($AE9-1),$AH$6:$AH$1505,0)),"")) | AJ9: =IF(OR($AI9="",$AC9=""),"",IF($AI9=$AC9,"ללא שינוי","מ-"&$AI9&" ל-"&$AC9))
Y10: =IF($C10="","",IF(COUNTA($I10:$K10)<3,"— חסרים נתונים",IF(AND($I10="תקין",$J10="תקין",$K10="תקין"),"רהוטה",IF(AND($I10="תקין",$J10="תקין"),"מדויקת ורציפה","אינה מדויקת או מקוטעת")))) | Z10: =IF($C10="","",IF(COUNTA($U10:$W10)<3,"",IF(AND($U10="מפותח",$V10="מפותח",$W10="מפותחת"),"מפותחת",IF((--($U10="דל"))+(--($V10="אינו מפותח"))+(--($W10="דלה"))>=2,"אינה מפותחת","חלקית")))) | AA10: =IF($C10="","",IF(COUNTA($M10,$N10,$O10)<3,"— חסרים נתונים",IF(OR($M10="נמוכה",(--($M10<>"תקינה"))+(--($N10<>"תקין"))+(--($O10<>"תקינה"))>=2),"ניכרת","אינה ניכרת"))) | AB10: =IF(OR($C10="",$Y10="",$AA10="",LEFT($Y10,1)="—",LEFT($AA10,1)="—"),"",IF($Z10="","— נדרשת הערכת כתיבה",IF($L10="","— חסרה הבנת הנקרא",IF($Y10="אינה מדויקת או מקוטעת",IF($AA10="ניכרת","מיקוד בשטף הקריאה ובכישורי שפה","מיקוד בשטף קריאה"),IF($AA10="ניכרת","מיקוד בכישורי שפה",IF(AND($L10="תקינה",$Z10="מפותחת"),"קוראים וכותבים מיומנים","מיקוד בהבנה והבעה")))))) | AC10: =IF(OR($AB10="",LEFT($AB10,1)="—"),"",IF(OR($AB10="מיקוד בשטף קריאה",$AB10="מיקוד בשטף הקריאה ובכישורי שפה"),"רמה א'",IF($AB10="קוראים וכותבים מיומנים","רמה ג'","רמה ב'"))) | AD10: =IF($AC10="","",MID(IF(AND($AC10="רמה א'",$AA10="ניכרת"),"; להוסיף עבודת אוצר מילים","")&IF($Z10="אינה מפותחת","; דגש על הבעה בכתב","")&IF($K10<>"תקין","; נדרש לעבוד על ההנגנה","")&IF($AK10<>"","; "&$AK10,""),3,400)) | AE10: =IF($F10="","",IF($F10="תחילת שנה",1,IF($F10="מחצית שנה",2,3))) | AF10: =IF(OR($B10="",$AC10="",$A10="",$F10=""),"",$B10&"|"&$A10&"|"&$F10&"|"&$AC10&"|"&COUNTIFS($B$6:$B10,$B10,$A$6:$A10,$A10,$F$6:$F10,$F10,$AC$6:$AC10,$AC10)) | AG10: =IF($C10="","",$C10&"|"&COUNTIFS($C$6:$C10,$C10)) | AH10: =IF(OR($C10="",$A10="",$AE10=""),"",$C10&"|"&$A10&"|"&$AE10) | AI10: =IF(OR($C10="",$AE10="",$AE10=1),"",IFERROR(INDEX($AC$6:$AC$1505,MATCH($C10&"|"&$A10&"|"&($AE10-1),$AH$6:$AH$1505,0)),"")) | AJ10: =IF(OR($AI10="",$AC10=""),"",IF($AI10=$AC10,"ללא שינוי","מ-"&$AI10&" ל-"&$AC10))
Y11: =IF($C11="","",IF(COUNTA($I11:$K11)<3,"— חסרים נתונים",IF(AND($I11="תקין",$J11="תקין",$K11="תקין"),"רהוטה",IF(AND($I11="תקין",$J11="תקין"),"מדויקת ורציפה","אינה מדויקת או מקוטעת")))) | Z11: =IF($C11="","",IF(COUNTA($U11:$W11)<3,"",IF(AND($U11="מפותח",$V11="מפותח",$W11="מפותחת"),"מפותחת",IF((--($U11="דל"))+(--($V11="אינו מפותח"))+(--($W11="דלה"))>=2,"אינה מפותחת","חלקית")))) | AA11: =IF($C11="","",IF(COUNTA($M11,$N11,$O11)<3,"— חסרים נתונים",IF(OR($M11="נמוכה",(--($M11<>"תקינה"))+(--($N11<>"תקין"))+(--($O11<>"תקינה"))>=2),"ניכרת","אינה ניכרת"))) | AB11: =IF(OR($C11="",$Y11="",$AA11="",LEFT($Y11,1)="—",LEFT($AA11,1)="—"),"",IF($Z11="","— נדרשת הערכת כתיבה",IF($L11="","— חסרה הבנת הנקרא",IF($Y11="אינה מדויקת או מקוטעת",IF($AA11="ניכרת","מיקוד בשטף הקריאה ובכישורי שפה","מיקוד בשטף קריאה"),IF($AA11="ניכרת","מיקוד בכישורי שפה",IF(AND($L11="תקינה",$Z11="מפותחת"),"קוראים וכותבים מיומנים","מיקוד בהבנה והבעה")))))) | AC11: =IF(OR($AB11="",LEFT($AB11,1)="—"),"",IF(OR($AB11="מיקוד בשטף קריאה",$AB11="מיקוד בשטף הקריאה ובכישורי שפה"),"רמה א'",IF($AB11="קוראים וכותבים מיומנים","רמה ג'","רמה ב'"))) | AD11: =IF($AC11="","",MID(IF(AND($AC11="רמה א'",$AA11="ניכרת"),"; להוסיף עבודת אוצר מילים","")&IF($Z11="אינה מפותחת","; דגש על הבעה בכתב","")&IF($K11<>"תקין","; נדרש לעבוד על ההנגנה","")&IF($AK11<>"","; "&$AK11,""),3,400)) | AE11: =IF($F11="","",IF($F11="תחילת שנה",1,IF($F11="מחצית שנה",2,3))) | AF11: =IF(OR($B11="",$AC11="",$A11="",$F11=""),"",$B11&"|"&$A11&"|"&$F11&"|"&$AC11&"|"&COUNTIFS($B$6:$B11,$B11,$A$6:$A11,$A11,$F$6:$F11,$F11,$AC$6:$AC11,$AC11)) | AG11: =IF($C11="","",$C11&"|"&COUNTIFS($C$6:$C11,$C11)) | AH11: =IF(OR($C11="",$A11="",$AE11=""),"",$C11&"|"&$A11&"|"&$AE11) | AI11: =IF(OR($C11="",$AE11="",$AE11=1),"",IFERROR(INDEX($AC$6:$AC$1505,MATCH($C11&"|"&$A11&"|"&($AE11-1),$AH$6:$AH$1505,0)),"")) | AJ11: =IF(OR($AI11="",$AC11=""),"",IF($AI11=$AC11,"ללא שינוי","מ-"&$AI11&" ל-"&$AC11))
Y12: =IF($C12="","",IF(COUNTA($I12:$K12)<3,"— חסרים נתונים",IF(AND($I12="תקין",$J12="תקין",$K12="תקין"),"רהוטה",IF(AND($I12="תקין",$J12="תקין"),"מדויקת ורציפה","אינה מדויקת או מקוטעת")))) | Z12: =IF($C12="","",IF(COUNTA($U12:$W12)<3,"",IF(AND($U12="מפותח",$V12="מפותח",$W12="מפותחת"),"מפותחת",IF((--($U12="דל"))+(--($V12="אינו מפותח"))+(--($W12="דלה"))>=2,"אינה מפותחת","חלקית")))) | AA12: =IF($C12="","",IF(COUNTA($M12,$N12,$O12)<3,"— חסרים נתונים",IF(OR($M12="נמוכה",(--($M12<>"תקינה"))+(--($N12<>"תקין"))+(--($O12<>"תקינה"))>=2),"ניכרת","אינה ניכרת"))) | AB12: =IF(OR($C12="",$Y12="",$AA12="",LEFT($Y12,1)="—",LEFT($AA12,1)="—"),"",IF($Z12="","— נדרשת הערכת כתיבה",IF($L12="","— חסרה הבנת הנקרא",IF($Y12="אינה מדויקת או מקוטעת",IF($AA12="ניכרת","מיקוד בשטף הקריאה ובכישורי שפה","מיקוד בשטף קריאה"),IF($AA12="ניכרת","מיקוד בכישורי שפה",IF(AND($L12="תקינה",$Z12="מפותחת"),"קוראים וכותבים מיומנים","מיקוד בהבנה והבעה")))))) | AC12: =IF(OR($AB12="",LEFT($AB12,1)="—"),"",IF(OR($AB12="מיקוד בשטף קריאה",$AB12="מיקוד בשטף הקריאה ובכישורי שפה"),"רמה א'",IF($AB12="קוראים וכותבים מיומנים","רמה ג'","רמה ב'"))) | AD12: =IF($AC12="","",MID(IF(AND($AC12="רמה א'",$AA12="ניכרת"),"; להוסיף עבודת אוצר מילים","")&IF($Z12="אינה מפותחת","; דגש על הבעה בכתב","")&IF($K12<>"תקין","; נדרש לעבוד על ההנגנה","")&IF($AK12<>"","; "&$AK12,""),3,400)) | AE12: =IF($F12="","",IF($F12="תחילת שנה",1,IF($F12="מחצית שנה",2,3))) | AF12: =IF(OR($B12="",$AC12="",$A12="",$F12=""),"",$B12&"|"&$A12&"|"&$F12&"|"&$AC12&"|"&COUNTIFS($B$6:$B12,$B12,$A$6:$A12,$A12,$F$6:$F12,$F12,$AC$6:$AC12,$AC12)) | AG12: =IF($C12="","",$C12&"|"&COUNTIFS($C$6:$C12,$C12)) | AH12: =IF(OR($C12="",$A12="",$AE12=""),"",$C12&"|"&$A12&"|"&$AE12) | AI12: =IF(OR($C12="",$AE12="",$AE12=1),"",IFERROR(INDEX($AC$6:$AC$1505,MATCH($C12&"|"&$A12&"|"&($AE12-1),$AH$6:$AH$1505,0)),"")) | AJ12: =IF(OR($AI12="",$AC12=""),"",IF($AI12=$AC12,"ללא שינוי","מ-"&$AI12&" ל-"&$AC12))
Y13: =IF($C13="","",IF(COUNTA($I13:$K13)<3,"— חסרים נתונים",IF(AND($I13="תקין",$J13="תקין",$K13="תקין"),"רהוטה",IF(AND($I13="תקין",$J13="תקין"),"מדויקת ורציפה","אינה מדויקת או מקוטעת")))) | Z13: =IF($C13="","",IF(COUNTA($U13:$W13)<3,"",IF(AND($U13="מפותח",$V13="מפותח",$W13="מפותחת"),"מפותחת",IF((--($U13="דל"))+(--($V13="אינו מפותח"))+(--($W13="דלה"))>=2,"אינה מפותחת","חלקית")))) | AA13: =IF($C13="","",IF(COUNTA($M13,$N13,$O13)<3,"— חסרים נתונים",IF(OR($M13="נמוכה",(--($M13<>"תקינה"))+(--($N13<>"תקין"))+(--($O13<>"תקינה"))>=2),"ניכרת","אינה ניכרת"))) | AB13: =IF(OR($C13="",$Y13="",$AA13="",LEFT($Y13,1)="—",LEFT($AA13,1)="—"),"",IF($Z13="","— נדרשת הערכת כתיבה",IF($L13="","— חסרה הבנת הנקרא",IF($Y13="אינה מדויקת או מקוטעת",IF($AA13="ניכרת","מיקוד בשטף הקריאה ובכישורי שפה","מיקוד בשטף קריאה"),IF($AA13="ניכרת","מיקוד בכישורי שפה",IF(AND($L13="תקינה",$Z13="מפותחת"),"קוראים וכותבים מיומנים","מיקוד בהבנה והבעה")))))) | AC13: =IF(OR($AB13="",LEFT($AB13,1)="—"),"",IF(OR($AB13="מיקוד בשטף קריאה",$AB13="מיקוד בשטף הקריאה ובכישורי שפה"),"רמה א'",IF($AB13="קוראים וכותבים מיומנים","רמה ג'","רמה ב'"))) | AD13: =IF($AC13="","",MID(IF(AND($AC13="רמה א'",$AA13="ניכרת"),"; להוסיף עבודת אוצר מילים","")&IF($Z13="אינה מפותחת","; דגש על הבעה בכתב","")&IF($K13<>"תקין","; נדרש לעבוד על ההנגנה","")&IF($AK13<>"","; "&$AK13,""),3,400)) | AE13: =IF($F13="","",IF($F13="תחילת שנה",1,IF($F13="מחצית שנה",2,3))) | AF13: =IF(OR($B13="",$AC13="",$A13="",$F13=""),"",$B13&"|"&$A13&"|"&$F13&"|"&$AC13&"|"&COUNTIFS($B$6:$B13,$B13,$A$6:$A13,$A13,$F$6:$F13,$F13,$AC$6:$AC13,$AC13)) | AG13: =IF($C13="","",$C13&"|"&COUNTIFS($C$6:$C13,$C13)) | AH13: =IF(OR($C13="",$A13="",$AE13=""),"",$C13&"|"&$A13&"|"&$AE13) | AI13: =IF(OR($C13="",$AE13="",$AE13=1),"",IFERROR(INDEX($AC$6:$AC$1505,MATCH($C13&"|"&$A13&"|"&($AE13-1),$AH$6:$AH$1505,0)),"")) | AJ13: =IF(OR($AI13="",$AC13=""),"",IF($AI13=$AC13,"ללא שינוי","מ-"&$AI13&" ל-"&$AC13))
Y14: =IF($C14="","",IF(COUNTA($I14:$K14)<3,"— חסרים נתונים",IF(AND($I14="תקין",$J14="תקין",$K14="תקין"),"רהוטה",IF(AND($I14="תקין",$J14="תקין"),"מדויקת ורציפה","אינה מדויקת או מקוטעת")))) | Z14: =IF($C14="","",IF(COUNTA($U14:$W14)<3,"",IF(AND($U14="מפותח",$V14="מפותח",$W14="מפותחת"),"מפותחת",IF((--($U14="דל"))+(--($V14="אינו מפותח"))+(--($W14="דלה"))>=2,"אינה מפותחת","חלקית")))) | AA14: =IF($C14="","",IF(COUNTA($M14,$N14,$O14)<3,"— חסרים נתונים",IF(OR($M14="נמוכה",(--($M14<>"תקינה"))+(--($N14<>"תקין"))+(--($O14<>"תקינה"))>=2),"ניכרת","אינה ניכרת"))) | AB14: =IF(OR($C14="",$Y14="",$AA14="",LEFT($Y14,1)="—",LEFT($AA14,1)="—"),"",IF($Z14="","— נדרשת הערכת כתיבה",IF($L14="","— חסרה הבנת הנקרא",IF($Y14="אינה מדויקת או מקוטעת",IF($AA14="ניכרת","מיקוד בשטף הקריאה ובכישורי שפה","מיקוד בשטף קריאה"),IF($AA14="ניכרת","מיקוד בכישורי שפה",IF(AND($L14="תקינה",$Z14="מפותחת"),"קוראים וכותבים מיומנים","מיקוד בהבנה והבעה")))))) | AC14: =IF(OR($AB14="",LEFT($AB14,1)="—"),"",IF(OR($AB14="מיקוד בשטף קריאה",$AB14="מיקוד בשטף הקריאה ובכישורי שפה"),"רמה א'",IF($AB14="קוראים וכותבים מיומנים","רמה ג'","רמה ב'"))) | AD14: =IF($AC14="","",MID(IF(AND($AC14="רמה א'",$AA14="ניכרת"),"; להוסיף עבודת אוצר מילים","")&IF($Z14="אינה מפותחת","; דגש על הבעה בכתב","")&IF($K14<>"תקין","; נדרש לעבוד על ההנגנה","")&IF($AK14<>"","; "&$AK14,""),3,400)) | AE14: =IF($F14="","",IF($F14="תחילת שנה",1,IF($F14="מחצית שנה",2,3))) | AF14: =IF(OR($B14="",$AC14="",$A14="",$F14=""),"",$B14&"|"&$A14&"|"&$F14&"|"&$AC14&"|"&COUNTIFS($B$6:$B14,$B14,$A$6:$A14,$A14,$F$6:$F14,$F14,$AC$6:$AC14,$AC14)) | AG14: =IF($C14="","",$C14&"|"&COUNTIFS($C$6:$C14,$C14)) | AH14: =IF(OR($C14="",$A14="",$AE14=""),"",$C14&"|"&$A14&"|"&$AE14) | AI14: =IF(OR($C14="",$AE14="",$AE14=1),"",IFERROR(INDEX($AC$6:$AC$1505,MATCH($C14&"|"&$A14&"|"&($AE14-1),$AH$6:$AH$1505,0)),"")) | AJ14: =IF(OR($AI14="",$AC14=""),"",IF($AI14=$AC14,"ללא שינוי","מ-"&$AI14&" ל-"&$AC14))
Y15: =IF($C15="","",IF(COUNTA($I15:$K15)<3,"— חסרים נתונים",IF(AND($I15="תקין",$J15="תקין",$K15="תקין"),"רהוטה",IF(AND($I15="תקין",$J15="תקין"),"מדויקת ורציפה","אינה מדויקת או מקוטעת")))) | Z15: =IF($C15="","",IF(COUNTA($U15:$W15)<3,"",IF(AND($U15="מפותח",$V15="מפותח",$W15="מפותחת"),"מפותחת",IF((--($U15="דל"))+(--($V15="אינו מפותח"))+(--($W15="דלה"))>=2,"אינה מפותחת","חלקית")))) | AA15: =IF($C15="","",IF(COUNTA($M15,$N15,$O15)<3,"— חסרים נתונים",IF(OR($M15="נמוכה",(--($M15<>"תקינה"))+(--($N15<>"תקין"))+(--($O15<>"תקינה"))>=2),"ניכרת","אינה ניכרת"))) | AB15: =IF(OR($C15="",$Y15="",$AA15="",LEFT($Y15,1)="—",LEFT($AA15,1)="—"),"",IF($Z15="","— נדרשת הערכת כתיבה",IF($L15="","— חסרה הבנת הנקרא",IF($Y15="אינה מדויקת או מקוטעת",IF($AA15="ניכרת","מיקוד בשטף הקריאה ובכישורי שפה","מיקוד בשטף קריאה"),IF($AA15="ניכרת","מיקוד בכישורי שפה",IF(AND($L15="תקינה",$Z15="מפותחת"),"קוראים וכותבים מיומנים","מיקוד בהבנה והבעה")))))) | AC15: =IF(OR($AB15="",LEFT($AB15,1)="—"),"",IF(OR($AB15="מיקוד בשטף קריאה",$AB15="מיקוד בשטף הקריאה ובכישורי שפה"),"רמה א'",IF($AB15="קוראים וכותבים מיומנים","רמה ג'","רמה ב'"))) | AD15: =IF($AC15="","",MID(IF(AND($AC15="רמה א'",$AA15="ניכרת"),"; להוסיף עבודת אוצר מילים","")&IF($Z15="אינה מפותחת","; דגש על הבעה בכתב","")&IF($K15<>"תקין","; נדרש לעבוד על ההנגנה","")&IF($AK15<>"","; "&$AK15,""),3,400)) | AE15: =IF($F15="","",IF($F15="תחילת שנה",1,IF($F15="מחצית שנה",2,3))) | AF15: =IF(OR($B15="",$AC15="",$A15="",$F15=""),"",$B15&"|"&$A15&"|"&$F15&"|"&$AC15&"|"&COUNTIFS($B$6:$B15,$B15,$A$6:$A15,$A15,$F$6:$F15,$F15,$AC$6:$AC15,$AC15)) | AG15: =IF($C15="","",$C15&"|"&COUNTIFS($C$6:$C15,$C15)) | AH15: =IF(OR($C15="",$A15="",$AE15=""),"",$C15&"|"&$A15&"|"&$AE15) | AI15: =IF(OR($C15="",$AE15="",$AE15=1),"",IFERROR(INDEX($AC$6:$AC$1505,MATCH($C15&"|"&$A15&"|"&($AE15-1),$AH$6:$AH$1505,0)),"")) | AJ15: =IF(OR($AI15="",$AC15=""),"",IF($AI15=$AC15,"ללא שינוי","מ-"&$AI15&" ל-"&$AC15))
Y16: =IF($C16="","",IF(COUNTA($I16:$K16)<3,"— חסרים נתונים",IF(AND($I16="תקין",$J16="תקין",$K16="תקין"),"רהוטה",IF(AND($I16="תקין",$J16="תקין"),"מדויקת ורציפה","אינה מדויקת או מקוטעת")))) | Z16: =IF($C16="","",IF(COUNTA($U16:$W16)<3,"",IF(AND($U16="מפותח",$V16="מפותח",$W16="מפותחת"),"מפותחת",IF((--($U16="דל"))+(--($V16="אינו מפותח"))+(--($W16="דלה"))>=2,"אינה מפותחת","חלקית")))) | AA16: =IF($C16="","",IF(COUNTA($M16,$N16,$O16)<3,"— חסרים נתונים",IF(OR($M16="נמוכה",(--($M16<>"תקינה"))+(--($N16<>"תקין"))+(--($O16<>"תקינה"))>=2),"ניכרת","אינה ניכרת"))) | AB16: =IF(OR($C16="",$Y16="",$AA16="",LEFT($Y16,1)="—",LEFT($AA16,1)="—"),"",IF($Z16="","— נדרשת הערכת כתיבה",IF($L16="","— חסרה הבנת הנקרא",IF($Y16="אינה מדויקת או מקוטעת",IF($AA16="ניכרת","מיקוד בשטף הקריאה ובכישורי שפה","מיקוד בשטף קריאה"),IF($AA16="ניכרת","מיקוד בכישורי שפה",IF(AND($L16="תקינה",$Z16="מפותחת"),"קוראים וכותבים מיומנים","מיקוד בהבנה והבעה")))))) | AC16: =IF(OR($AB16="",LEFT($AB16,1)="—"),"",IF(OR($AB16="מיקוד בשטף קריאה",$AB16="מיקוד בשטף הקריאה ובכישורי שפה"),"רמה א'",IF($AB16="קוראים וכותבים מיומנים","רמה ג'","רמה ב'"))) | AD16: =IF($AC16="","",MID(IF(AND($AC16="רמה א'",$AA16="ניכרת"),"; להוסיף עבודת אוצר מילים","")&IF($Z16="אינה מפותחת","; דגש על הבעה בכתב","")&IF($K16<>"תקין","; נדרש לעבוד על ההנגנה","")&IF($AK16<>"","; "&$AK16,""),3,400)) | AE16: =IF($F16="","",IF($F16="תחילת שנה",1,IF($F16="מחצית שנה",2,3))) | AF16: =IF(OR($B16="",$AC16="",$A16="",$F16=""),"",$B16&"|"&$A16&"|"&$F16&"|"&$AC16&"|"&COUNTIFS($B$6:$B16,$B16,$A$6:$A16,$A16,$F$6:$F16,$F16,$AC$6:$AC16,$AC16)) | AG16: =IF($C16="","",$C16&"|"&COUNTIFS($C$6:$C16,$C16)) | AH16: =IF(OR($C16="",$A16="",$AE16=""),"",$C16&"|"&$A16&"|"&$AE16) | AI16: =IF(OR($C16="",$AE16="",$AE16=1),"",IFERROR(INDEX($AC$6:$AC$1505,MATCH($C16&"|"&$A16&"|"&($AE16-1),$AH$6:$AH$1505,0)),"")) | AJ16: =IF(OR($AI16="",$AC16=""),"",IF($AI16=$AC16,"ללא שינוי","מ-"&$AI16&" ל-"&$AC16))
Y17: =IF($C17="","",IF(COUNTA($I17:$K17)<3,"— חסרים נתונים",IF(AND($I17="תקין",$J17="תקין",$K17="תקין"),"רהוטה",IF(AND($I17="תקין",$J17="תקין"),"מדויקת ורציפה","אינה מדויקת או מקוטעת")))) | Z17: =IF($C17="","",IF(COUNTA($U17:$W17)<3,"",IF(AND($U17="מפותח",$V17="מפותח",$W17="מפותחת"),"מפותחת",IF((--($U17="דל"))+(--($V17="אינו מפותח"))+(--($W17="דלה"))>=2,"אינה מפותחת","חלקית")))) | AA17: =IF($C17="","",IF(COUNTA($M17,$N17,$O17)<3,"— חסרים נתונים",IF(OR($M17="נמוכה",(--($M17<>"תקינה"))+(--($N17<>"תקין"))+(--($O17<>"תקינה"))>=2),"ניכרת","אינה ניכרת"))) | AB17: =IF(OR($C17="",$Y17="",$AA17="",LEFT($Y17,1)="—",LEFT($AA17,1)="—"),"",IF($Z17="","— נדרשת הערכת כתיבה",IF($L17="","— חסרה הבנת הנקרא",IF($Y17="אינה מדויקת או מקוטעת",IF($AA17="ניכרת","מיקוד בשטף הקריאה ובכישורי שפה","מיקוד בשטף קריאה"),IF($AA17="ניכרת","מיקוד בכישורי שפה",IF(AND($L17="תקינה",$Z17="מפותחת"),"קוראים וכותבים מיומנים","מיקוד בהבנה והבעה")))))) | AC17: =IF(OR($AB17="",LEFT($AB17,1)="—"),"",IF(OR($AB17="מיקוד בשטף קריאה",$AB17="מיקוד בשטף הקריאה ובכישורי שפה"),"רמה א'",IF($AB17="קוראים וכותבים מיומנים","רמה ג'","רמה ב'"))) | AD17: =IF($AC17="","",MID(IF(AND($AC17="רמה א'",$AA17="ניכרת"),"; להוסיף עבודת אוצר מילים","")&IF($Z17="אינה מפותחת","; דגש על הבעה בכתב","")&IF($K17<>"תקין","; נדרש לעבוד על ההנגנה","")&IF($AK17<>"","; "&$AK17,""),3,400)) | AE17: =IF($F17="","",IF($F17="תחילת שנה",1,IF($F17="מחצית שנה",2,3))) | AF17: =IF(OR($B17="",$AC17="",$A17="",$F17=""),"",$B17&"|"&$A17&"|"&$F17&"|"&$AC17&"|"&COUNTIFS($B$6:$B17,$B17,$A$6:$A17,$A17,$F$6:$F17,$F17,$AC$6:$AC17,$AC17)) | AG17: =IF($C17="","",$C17&"|"&COUNTIFS($C$6:$C17,$C17)) | AH17: =IF(OR($C17="",$A17="",$AE17=""),"",$C17&"|"&$A17&"|"&$AE17) | AI17: =IF(OR($C17="",$AE17="",$AE17=1),"",IFERROR(INDEX($AC$6:$AC$1505,MATCH($C17&"|"&$A17&"|"&($AE17-1),$AH$6:$AH$1505,0)),"")) | AJ17: =IF(OR($AI17="",$AC17=""),"",IF($AI17=$AC17,"ללא שינוי","מ-"&$AI17&" ל-"&$AC17))
... Y1505: =IF($C1505="","",IF(COUNTA($I1505:$K1505)<3,"— חסרים נתונים",IF(AND($I1505="תקין",$J1505="תקין",$K1505="תקין"),"רהוטה",IF(AND($I1505="תקין",$J1505="תקין"),"מדויקת ורציפה","אינה מדויקת או מקוטעת")))) | Z1505: =IF($C1505="","",IF(COUNTA($U1505:$W1505)<3,"",IF(AND($U1505="מפותח",$V1505="מפותח",$W1505="מפותחת"),"מפותחת",IF((--($U1505="דל"))+(--($V1505="אינו מפותח"))+(--($W1505="דלה"))>=2,"אינה מפותחת","חלקית")))) | AA1505: =IF($C1505="","",IF(COUNTA($M1505,$N1505,$O1505)<3,"— חסרים נתונים",IF(OR($M1505="נמוכה",(--($M1505<>"תקינה"))+(--($N1505<>"תקין"))+(--($O1505<>"תקינה"))>=2),"ניכרת","אינה ניכרת"))) | AB1505: =IF(OR($C1505="",$Y1505="",$AA1505="",LEFT($Y1505,1)="—",LEFT($AA1505,1)="—"),"",IF($Z1505="","— נדרשת הערכת כתיבה",IF($L1505="","— חסרה הבנת הנקרא",IF($Y1505="אינה מדויקת או מקוטעת",IF($AA1505="ניכרת","מיקוד בשטף הקריאה ובכישורי שפה","מיקוד בשטף קריאה"),IF($AA1505="ניכרת","מיקוד בכישורי שפה",IF(AND($L1505="תקינה",$Z1505="מפותחת"),"קוראים וכותבים מיומנים","מיקוד בהבנה והבעה")))))) | AC1505: =IF(OR($AB1505="",LEFT($AB1505,1)="—"),"",IF(OR($AB1505="מיקוד בשטף קריאה",$AB1505="מיקוד בשטף הקריאה ובכישורי שפה"),"רמה א'",IF($AB1505="קוראים וכותבים מיומנים","רמה ג'","רמה ב'"))) | AD1505: =IF($AC1505="","",MID(IF(AND($AC1505="רמה א'",$AA1505="ניכרת"),"; להוסיף עבודת אוצר מילים","")&IF($Z1505="אינה מפותחת","; דגש על הבעה בכתב","")&IF($K1505<>"תקין","; נדרש לעבוד על ההנגנה","")&IF($AK1505<>"","; "&$AK1505,""),3,400)) | AE1505: =IF($F1505="","",IF($F1505="תחילת שנה",1,IF($F1505="מחצית שנה",2,3))) | AF1505: =IF(OR($B1505="",$AC1505="",$A1505="",$F1505=""),"",$B1505&"|"&$A1505&"|"&$F1505&"|"&$AC1505&"|"&COUNTIFS($B$6:$B1505,$B1505,$A$6:$A1505,$A1505,$F$6:$F1505,$F1505,$AC$6:$AC1505,$AC1505)) | AG1505: =IF($C1505="","",$C1505&"|"&COUNTIFS($C$6:$C1505,$C1505)) | AH1505: =IF(OR($C1505="",$A1505="",$AE1505=""),"",$C1505&"|"&$A1505&"|"&$AE1505) | AI1505: =IF(OR($C1505="",$AE1505="",$AE1505=1),"",IFERROR(INDEX($AC$6:$AC$1505,MATCH($C1505&"|"&$A1505&"|"&($AE1505-1),$AH$6:$AH$1505,0)),"")) | AJ1505: =IF(OR($AI1505="",$AC1505=""),"",IF($AI1505=$AC1505,"ללא שינוי","מ-"&$AI1505&" ל-"&$AC1505))

Sheet הזנה רכישה
A1: גיליון הזנה — שלב רכישת הקריאה והכתיבה
A2: שורה לכל תלמיד בכל פעימה. אין לדרוס שורות קודמות.
A3: תלמידים שהוזנה להם רשימת מילים בלבד (קבוצה רביעית: הקניית קריאה). מתמלא אוטומטית מהמקור. אין להקליד בו.
A4: זיהוי | G4: רכישת הקריאה | Q4: מחושב
A5: שנת לימודים | B5: כיתה | C5: תלמיד (כיתה/מספר) | D5: מורה | E5: תאריך | F5: פעימה | G5: ידיעת אותיות | H5: קשרי אות-צליל | I5: מודעות פונולוגית | J5: פענוח בסימני ניקוד | K5: אוטומטיות הפענוח | L5: קריאה גלובלית | M5: הבנת הנקרא | N5: כתיב פונטי | O5: הפקה בכתב | P5: ביטחון והנאה | Q5: הפרופיל (מחושב) | R5: קבוצת ההוראה | S5: סדר פעימה | T5: מפתח קבוצה | U5: מפתח תלמיד | V5: מפתח קודם | W5: הפרופיל הקודם | X5: תנועה
Q6: =IF($C6="","",IF($J6="","— חסרים נתונים",IF($J6="טרם מפענח","פרופיל 5",IF($J6="קמץ/פתח/חטף-פתח ושוואים","פרופיל 4",IF($J6="2-3 סימני ניקוד","פרופיל 3",IF($J6="4-5 סימני ניקוד","פרופיל 2",IF(AND($O6="משפטים וקטעים קצרים",OR($M6="מבין",$M6="מבין לרוב")),"פרופיל 1","פרופיל 2"))))))) | R6: =IF($C6="","",IF(OR($Q6="",LEFT($Q6,1)="—"),"קבוצה רביעית",IF($Q6="פרופיל 5","קבוצת תשתיות",IF(OR($Q6="פרופיל 4",$Q6="פרופיל 3"),"קבוצת רכישה","קבוצת ביסוס")))) | S6: =IF($F6="","",IF($F6="תחילת שנה",1,IF($F6="מחצית שנה",2,3))) | T6: =IF(OR($B6="",$R6="",$A6="",$F6=""),"",$B6&"|"&$A6&"|"&$F6&"|"&$R6&"|"&COUNTIFS($B$6:$B6,$B6,$A$6:$A6,$A6,$F$6:$F6,$F6,$R$6:$R6,$R6)) | U6: =IF($C6="","",$C6&"|"&COUNTIFS($C$6:$C6,$C6)) | V6: =IF(OR($C6="",$A6="",$S6=""),"",$C6&"|"&$A6&"|"&$S6) | W6: =IF(OR($C6="",$S6="",$S6=1),"",IFERROR(INDEX($Q$6:$Q$1505,MATCH($C6&"|"&$A6&"|"&($S6-1),$V$6:$V$1505,0)),"")) | X6: =IF(OR($W6="",$Q6="",LEFT($Q6,1)="—"),"",IF($W6=$Q6,"ללא שינוי","מ-"&$W6&" ל-"&$Q6))
Q7: =IF($C7="","",IF($J7="","— חסרים נתונים",IF($J7="טרם מפענח","פרופיל 5",IF($J7="קמץ/פתח/חטף-פתח ושוואים","פרופיל 4",IF($J7="2-3 סימני ניקוד","פרופיל 3",IF($J7="4-5 סימני ניקוד","פרופיל 2",IF(AND($O7="משפטים וקטעים קצרים",OR($M7="מבין",$M7="מבין לרוב")),"פרופיל 1","פרופיל 2"))))))) | R7: =IF($C7="","",IF(OR($Q7="",LEFT($Q7,1)="—"),"קבוצה רביעית",IF($Q7="פרופיל 5","קבוצת תשתיות",IF(OR($Q7="פרופיל 4",$Q7="פרופיל 3"),"קבוצת רכישה","קבוצת ביסוס")))) | S7: =IF($F7="","",IF($F7="תחילת שנה",1,IF($F7="מחצית שנה",2,3))) | T7: =IF(OR($B7="",$R7="",$A7="",$F7=""),"",$B7&"|"&$A7&"|"&$F7&"|"&$R7&"|"&COUNTIFS($B$6:$B7,$B7,$A$6:$A7,$A7,$F$6:$F7,$F7,$R$6:$R7,$R7)) | U7: =IF($C7="","",$C7&"|"&COUNTIFS($C$6:$C7,$C7)) | V7: =IF(OR($C7="",$A7="",$S7=""),"",$C7&"|"&$A7&"|"&$S7) | W7: =IF(OR($C7="",$S7="",$S7=1),"",IFERROR(INDEX($Q$6:$Q$1505,MATCH($C7&"|"&$A7&"|"&($S7-1),$V$6:$V$1505,0)),"")) | X7: =IF(OR($W7="",$Q7="",LEFT($Q7,1)="—"),"",IF($W7=$Q7,"ללא שינוי","מ-"&$W7&" ל-"&$Q7))
Q8: =IF($C8="","",IF($J8="","— חסרים נתונים",IF($J8="טרם מפענח","פרופיל 5",IF($J8="קמץ/פתח/חטף-פתח ושוואים","פרופיל 4",IF($J8="2-3 סימני ניקוד","פרופיל 3",IF($J8="4-5 סימני ניקוד","פרופיל 2",IF(AND($O8="משפטים וקטעים קצרים",OR($M8="מבין",$M8="מבין לרוב")),"פרופיל 1","פרופיל 2"))))))) | R8: =IF($C8="","",IF(OR($Q8="",LEFT($Q8,1)="—"),"קבוצה רביעית",IF($Q8="פרופיל 5","קבוצת תשתיות",IF(OR($Q8="פרופיל 4",$Q8="פרופיל 3"),"קבוצת רכישה","קבוצת ביסוס")))) | S8: =IF($F8="","",IF($F8="תחילת שנה",1,IF($F8="מחצית שנה",2,3))) | T8: =IF(OR($B8="",$R8="",$A8="",$F8=""),"",$B8&"|"&$A8&"|"&$F8&"|"&$R8&"|"&COUNTIFS($B$6:$B8,$B8,$A$6:$A8,$A8,$F$6:$F8,$F8,$R$6:$R8,$R8)) | U8: =IF($C8="","",$C8&"|"&COUNTIFS($C$6:$C8,$C8)) | V8: =IF(OR($C8="",$A8="",$S8=""),"",$C8&"|"&$A8&"|"&$S8) | W8: =IF(OR($C8="",$S8="",$S8=1),"",IFERROR(INDEX($Q$6:$Q$1505,MATCH($C8&"|"&$A8&"|"&($S8-1),$V$6:$V$1505,0)),"")) | X8: =IF(OR($W8="",$Q8="",LEFT($Q8,1)="—"),"",IF($W8=$Q8,"ללא שינוי","מ-"&$W8&" ל-"&$Q8))
Q9: =IF($C9="","",IF($J9="","— חסרים נתונים",IF($J9="טרם מפענח","פרופיל 5",IF($J9="קמץ/פתח/חטף-פתח ושוואים","פרופיל 4",IF($J9="2-3 סימני ניקוד","פרופיל 3",IF($J9="4-5 סימני ניקוד","פרופיל 2",IF(AND($O9="משפטים וקטעים קצרים",OR($M9="מבין",$M9="מבין לרוב")),"פרופיל 1","פרופיל 2"))))))) | R9: =IF($C9="","",IF(OR($Q9="",LEFT($Q9,1)="—"),"קבוצה רביעית",IF($Q9="פרופיל 5","קבוצת תשתיות",IF(OR($Q9="פרופיל 4",$Q9="פרופיל 3"),"קבוצת רכישה","קבוצת ביסוס")))) | S9: =IF($F9="","",IF($F9="תחילת שנה",1,IF($F9="מחצית שנה",2,3))) | T9: =IF(OR($B9="",$R9="",$A9="",$F9=""),"",$B9&"|"&$A9&"|"&$F9&"|"&$R9&"|"&COUNTIFS($B$6:$B9,$B9,$A$6:$A9,$A9,$F$6:$F9,$F9,$R$6:$R9,$R9)) | U9: =IF($C9="","",$C9&"|"&COUNTIFS($C$6:$C9,$C9)) | V9: =IF(OR($C9="",$A9="",$S9=""),"",$C9&"|"&$A9&"|"&$S9) | W9: =IF(OR($C9="",$S9="",$S9=1),"",IFERROR(INDEX($Q$6:$Q$1505,MATCH($C9&"|"&$A9&"|"&($S9-1),$V$6:$V$1505,0)),"")) | X9: =IF(OR($W9="",$Q9="",LEFT($Q9,1)="—"),"",IF($W9=$Q9,"ללא שינוי","מ-"&$W9&" ל-"&$Q9))
Q10: =IF($C10="","",IF($J10="","— חסרים נתונים",IF($J10="טרם מפענח","פרופיל 5",IF($J10="קמץ/פתח/חטף-פתח ושוואים","פרופיל 4",IF($J10="2-3 סימני ניקוד","פרופיל 3",IF($J10="4-5 סימני ניקוד","פרופיל 2",IF(AND($O10="משפטים וקטעים קצרים",OR($M10="מבין",$M10="מבין לרוב")),"פרופיל 1","פרופיל 2"))))))) | R10: =IF($C10="","",IF(OR($Q10="",LEFT($Q10,1)="—"),"קבוצה רביעית",IF($Q10="פרופיל 5","קבוצת תשתיות",IF(OR($Q10="פרופיל 4",$Q10="פרופיל 3"),"קבוצת רכישה","קבוצת ביסוס")))) | S10: =IF($F10="","",IF($F10="תחילת שנה",1,IF($F10="מחצית שנה",2,3))) | T10: =IF(OR($B10="",$R10="",$A10="",$F10=""),"",$B10&"|"&$A10&"|"&$F10&"|"&$R10&"|"&COUNTIFS($B$6:$B10,$B10,$A$6:$A10,$A10,$F$6:$F10,$F10,$R$6:$R10,$R10)) | U10: =IF($C10="","",$C10&"|"&COUNTIFS($C$6:$C10,$C10)) | V10: =IF(OR($C10="",$A10="",$S10=""),"",$C10&"|"&$A10&"|"&$S10) | W10: =IF(OR($C10="",$S10="",$S10=1),"",IFERROR(INDEX($Q$6:$Q$1505,MATCH($C10&"|"&$A10&"|"&($S10-1),$V$6:$V$1505,0)),"")) | X10: =IF(OR($W10="",$Q10="",LEFT($Q10,1)="—"),"",IF($W10=$Q10,"ללא שינוי","מ-"&$W10&" ל-"&$Q10))
Q11: =IF($C11="","",IF($J11="","— חסרים נתונים",IF($J11="טרם מפענח","פרופיל 5",IF($J11="קמץ/פתח/חטף-פתח ושוואים","פרופיל 4",IF($J11="2-3 סימני ניקוד","פרופיל 3",IF($J11="4-5 סימני ניקוד","פרופיל 2",IF(AND($O11="משפטים וקטעים קצרים",OR($M11="מבין",$M11="מבין לרוב")),"פרופיל 1","פרופיל 2"))))))) | R11: =IF($C11="","",IF(OR($Q11="",LEFT($Q11,1)="—"),"קבוצה רביעית",IF($Q11="פרופיל 5","קבוצת תשתיות",IF(OR($Q11="פרופיל 4",$Q11="פרופיל 3"),"קבוצת רכישה","קבוצת ביסוס")))) | S11: =IF($F11="","",IF($F11="תחילת שנה",1,IF($F11="מחצית שנה",2,3))) | T11: =IF(OR($B11="",$R11="",$A11="",$F11=""),"",$B11&"|"&$A11&"|"&$F11&"|"&$R11&"|"&COUNTIFS($B$6:$B11,$B11,$A$6:$A11,$A11,$F$6:$F11,$F11,$R$6:$R11,$R11)) | U11: =IF($C11="","",$C11&"|"&COUNTIFS($C$6:$C11,$C11)) | V11: =IF(OR($C11="",$A11="",$S11=""),"",$C11&"|"&$A11&"|"&$S11) | W11: =IF(OR($C11="",$S11="",$S11=1),"",IFERROR(INDEX($Q$6:$Q$1505,MATCH($C11&"|"&$A11&"|"&($S11-1),$V$6:$V$1505,0)),"")) | X11: =IF(OR($W11="",$Q11="",LEFT($Q11,1)="—"),"",IF($W11=$Q11,"ללא שינוי","מ-"&$W11&" ל-"&$Q11))
Q12: =IF($C12="","",IF($J12="","— חסרים נתונים",IF($J12="טרם מפענח","פרופיל 5",IF($J12="קמץ/פתח/חטף-פתח ושוואים","פרופיל 4",IF($J12="2-3 סימני ניקוד","פרופיל 3",IF($J12="4-5 סימני ניקוד","פרופיל 2",IF(AND($O12="משפטים וקטעים קצרים",OR($M12="מבין",$M12="מבין לרוב")),"פרופיל 1","פרופיל 2"))))))) | R12: =IF($C12="","",IF(OR($Q12="",LEFT($Q12,1)="—"),"קבוצה רביעית",IF($Q12="פרופיל 5","קבוצת תשתיות",IF(OR($Q12="פרופיל 4",$Q12="פרופיל 3"),"קבוצת רכישה","קבוצת ביסוס")))) | S12: =IF($F12="","",IF($F12="תחילת שנה",1,IF($F12="מחצית שנה",2,3))) | T12: =IF(OR($B12="",$R12="",$A12="",$F12=""),"",$B12&"|"&$A12&"|"&$F12&"|"&$R12&"|"&COUNTIFS($B$6:$B12,$B12,$A$6:$A12,$A12,$F$6:$F12,$F12,$R$6:$R12,$R12)) | U12: =IF($C12="","",$C12&"|"&COUNTIFS($C$6:$C12,$C12)) | V12: =IF(OR($C12="",$A12="",$S12=""),"",$C12&"|"&$A12&"|"&$S12) | W12: =IF(OR($C12="",$S12="",$S12=1),"",IFERROR(INDEX($Q$6:$Q$1505,MATCH($C12&"|"&$A12&"|"&($S12-1),$V$6:$V$1505,0)),"")) | X12: =IF(OR($W12="",$Q12="",LEFT($Q12,1)="—"),"",IF($W12=$Q12,"ללא שינוי","מ-"&$W12&" ל-"&$Q12))
Q13: =IF($C13="","",IF($J13="","— חסרים נתונים",IF($J13="טרם מפענח","פרופיל 5",IF($J13="קמץ/פתח/חטף-פתח ושוואים","פרופיל 4",IF($J13="2-3 סימני ניקוד","פרופיל 3",IF($J13="4-5 סימני ניקוד","פרופיל 2",IF(AND($O13="משפטים וקטעים קצרים",OR($M13="מבין",$M13="מבין לרוב")),"פרופיל 1","פרופיל 2"))))))) | R13: =IF($C13="","",IF(OR($Q13="",LEFT($Q13,1)="—"),"קבוצה רביעית",IF($Q13="פרופיל 5","קבוצת תשתיות",IF(OR($Q13="פרופיל 4",$Q13="פרופיל 3"),"קבוצת רכישה","קבוצת ביסוס")))) | S13: =IF($F13="","",IF($F13="תחילת שנה",1,IF($F13="מחצית שנה",2,3))) | T13: =IF(OR($B13="",$R13="",$A13="",$F13=""),"",$B13&"|"&$A13&"|"&$F13&"|"&$R13&"|"&COUNTIFS($B$6:$B13,$B13,$A$6:$A13,$A13,$F$6:$F13,$F13,$R$6:$R13,$R13)) | U13: =IF($C13="","",$C13&"|"&COUNTIFS($C$6:$C13,$C13)) | V13: =IF(OR($C13="",$A13="",$S13=""),"",$C13&"|"&$A13&"|"&$S13) | W13: =IF(OR($C13="",$S13="",$S13=1),"",IFERROR(INDEX($Q$6:$Q$1505,MATCH($C13&"|"&$A13&"|"&($S13-1),$V$6:$V$1505,0)),"")) | X13: =IF(OR($W13="",$Q13="",LEFT($Q13,1)="—"),"",IF($W13=$Q13,"ללא שינוי","מ-"&$W13&" ל-"&$Q13))
Q14: =IF($C14="","",IF($J14="","— חסרים נתונים",IF($J14="טרם מפענח","פרופיל 5",IF($J14="קמץ/פתח/חטף-פתח ושוואים","פרופיל 4",IF($J14="2-3 סימני ניקוד","פרופיל 3",IF($J14="4-5 סימני ניקוד","פרופיל 2",IF(AND($O14="משפטים וקטעים קצרים",OR($M14="מבין",$M14="מבין לרוב")),"פרופיל 1","פרופיל 2"))))))) | R14: =IF($C14="","",IF(OR($Q14="",LEFT($Q14,1)="—"),"קבוצה רביעית",IF($Q14="פרופיל 5","קבוצת תשתיות",IF(OR($Q14="פרופיל 4",$Q14="פרופיל 3"),"קבוצת רכישה","קבוצת ביסוס")))) | S14: =IF($F14="","",IF($F14="תחילת שנה",1,IF($F14="מחצית שנה",2,3))) | T14: =IF(OR($B14="",$R14="",$A14="",$F14=""),"",$B14&"|"&$A14&"|"&$F14&"|"&$R14&"|"&COUNTIFS($B$6:$B14,$B14,$A$6:$A14,$A14,$F$6:$F14,$F14,$R$6:$R14,$R14)) | U14: =IF($C14="","",$C14&"|"&COUNTIFS($C$6:$C14,$C14)) | V14: =IF(OR($C14="",$A14="",$S14=""),"",$C14&"|"&$A14&"|"&$S14) | W14: =IF(OR($C14="",$S14="",$S14=1),"",IFERROR(INDEX($Q$6:$Q$1505,MATCH($C14&"|"&$A14&"|"&($S14-1),$V$6:$V$1505,0)),"")) | X14: =IF(OR($W14="",$Q14="",LEFT($Q14,1)="—"),"",IF($W14=$Q14,"ללא שינוי","מ-"&$W14&" ל-"&$Q14))
Q15: =IF($C15="","",IF($J15="","— חסרים נתונים",IF($J15="טרם מפענח","פרופיל 5",IF($J15="קמץ/פתח/חטף-פתח ושוואים","פרופיל 4",IF($J15="2-3 סימני ניקוד","פרופיל 3",IF($J15="4-5 סימני ניקוד","פרופיל 2",IF(AND($O15="משפטים וקטעים קצרים",OR($M15="מבין",$M15="מבין לרוב")),"פרופיל 1","פרופיל 2"))))))) | R15: =IF($C15="","",IF(OR($Q15="",LEFT($Q15,1)="—"),"קבוצה רביעית",IF($Q15="פרופיל 5","קבוצת תשתיות",IF(OR($Q15="פרופיל 4",$Q15="פרופיל 3"),"קבוצת רכישה","קבוצת ביסוס")))) | S15: =IF($F15="","",IF($F15="תחילת שנה",1,IF($F15="מחצית שנה",2,3))) | T15: =IF(OR($B15="",$R15="",$A15="",$F15=""),"",$B15&"|"&$A15&"|"&$F15&"|"&$R15&"|"&COUNTIFS($B$6:$B15,$B15,$A$6:$A15,$A15,$F$6:$F15,$F15,$R$6:$R15,$R15)) | U15: =IF($C15="","",$C15&"|"&COUNTIFS($C$6:$C15,$C15)) | V15: =IF(OR($C15="",$A15="",$S15=""),"",$C15&"|"&$A15&"|"&$S15) | W15: =IF(OR($C15="",$S15="",$S15=1),"",IFERROR(INDEX($Q$6:$Q$1505,MATCH($C15&"|"&$A15&"|"&($S15-1),$V$6:$V$1505,0)),"")) | X15: =IF(OR($W15="",$Q15="",LEFT($Q15,1)="—"),"",IF($W15=$Q15,"ללא שינוי","מ-"&$W15&" ל-"&$Q15))
Q16: =IF($C16="","",IF($J16="","— חסרים נתונים",IF($J16="טרם מפענח","פרופיל 5",IF($J16="קמץ/פתח/חטף-פתח ושוואים","פרופיל 4",IF($J16="2-3 סימני ניקוד","פרופיל 3",IF($J16="4-5 סימני ניקוד","פרופיל 2",IF(AND($O16="משפטים וקטעים קצרים",OR($M16="מבין",$M16="מבין לרוב")),"פרופיל 1","פרופיל 2"))))))) | R16: =IF($C16="","",IF(OR($Q16="",LEFT($Q16,1)="—"),"קבוצה רביעית",IF($Q16="פרופיל 5","קבוצת תשתיות",IF(OR($Q16="פרופיל 4",$Q16="פרופיל 3"),"קבוצת רכישה","קבוצת ביסוס")))) | S16: =IF($F16="","",IF($F16="תחילת שנה",1,IF($F16="מחצית שנה",2,3))) | T16: =IF(OR($B16="",$R16="",$A16="",$F16=""),"",$B16&"|"&$A16&"|"&$F16&"|"&$R16&"|"&COUNTIFS($B$6:$B16,$B16,$A$6:$A16,$A16,$F$6:$F16,$F16,$R$6:$R16,$R16)) | U16: =IF($C16="","",$C16&"|"&COUNTIFS($C$6:$C16,$C16)) | V16: =IF(OR($C16="",$A16="",$S16=""),"",$C16&"|"&$A16&"|"&$S16) | W16: =IF(OR($C16="",$S16="",$S16=1),"",IFERROR(INDEX($Q$6:$Q$1505,MATCH($C16&"|"&$A16&"|"&($S16-1),$V$6:$V$1505,0)),"")) | X16: =IF(OR($W16="",$Q16="",LEFT($Q16,1)="—"),"",IF($W16=$Q16,"ללא שינוי","מ-"&$W16&" ל-"&$Q16))
Q17: =IF($C17="","",IF($J17="","— חסרים נתונים",IF($J17="טרם מפענח","פרופיל 5",IF($J17="קמץ/פתח/חטף-פתח ושוואים","פרופיל 4",IF($J17="2-3 סימני ניקוד","פרופיל 3",IF($J17="4-5 סימני ניקוד","פרופיל 2",IF(AND($O17="משפטים וקטעים קצרים",OR($M17="מבין",$M17="מבין לרוב")),"פרופיל 1","פרופיל 2"))))))) | R17: =IF($C17="","",IF(OR($Q17="",LEFT($Q17,1)="—"),"קבוצה רביעית",IF($Q17="פרופיל 5","קבוצת תשתיות",IF(OR($Q17="פרופיל 4",$Q17="פרופיל 3"),"קבוצת רכישה","קבוצת ביסוס")))) | S17: =IF($F17="","",IF($F17="תחילת שנה",1,IF($F17="מחצית שנה",2,3))) | T17: =IF(OR($B17="",$R17="",$A17="",$F17=""),"",$B17&"|"&$A17&"|"&$F17&"|"&$R17&"|"&COUNTIFS($B$6:$B17,$B17,$A$6:$A17,$A17,$F$6:$F17,$F17,$R$6:$R17,$R17)) | U17: =IF($C17="","",$C17&"|"&COUNTIFS($C$6:$C17,$C17)) | V17: =IF(OR($C17="",$A17="",$S17=""),"",$C17&"|"&$A17&"|"&$S17) | W17: =IF(OR($C17="",$S17="",$S17=1),"",IFERROR(INDEX($Q$6:$Q$1505,MATCH($C17&"|"&$A17&"|"&($S17-1),$V$6:$V$1505,0)),"")) | X17: =IF(OR($W17="",$Q17="",LEFT($Q17,1)="—"),"",IF($W17=$Q17,"ללא שינוי","מ-"&$W17&" ל-"&$Q17))
... Q1505: =IF($C1505="","",IF($J1505="","— חסרים נתונים",IF($J1505="טרם מפענח","פרופיל 5",IF($J1505="קמץ/פתח/חטף-פתח ושוואים","פרופיל 4",IF($J1505="2-3 סימני ניקוד","פרופיל 3",IF($J1505="4-5 סימני ניקוד","פרופיל 2",IF(AND($O1505="משפטים וקטעים קצרים",OR($M1505="מבין",$M1505="מבין לרוב")),"פרופיל 1","פרופיל 2"))))))) | R1505: =IF($C1505="","",IF(OR($Q1505="",LEFT($Q1505,1)="—"),"קבוצה רביעית",IF($Q1505="פרופיל 5","קבוצת תשתיות",IF(OR($Q1505="פרופיל 4",$Q1505="פרופיל 3"),"קבוצת רכישה","קבוצת ביסוס")))) | S1505: =IF($F1505="","",IF($F1505="תחילת שנה",1,IF($F1505="מחצית שנה",2,3))) | T1505: =IF(OR($B1505="",$R1505="",$A1505="",$F1505=""),"",$B1505&"|"&$A1505&"|"&$F1505&"|"&$R1505&"|"&COUNTIFS($B$6:$B1505,$B1505,$A$6:$A1505,$A1505,$F$6:$F1505,$F1505,$R$6:$R1505,$R1505)) | U1505: =IF($C1505="","",$C1505&"|"&COUNTIFS($C$6:$C1505,$C1505)) | V1505: =IF(OR($C1505="",$A1505="",$S1505=""),"",$C1505&"|"&$A1505&"|"&$S1505) | W1505: =IF(OR($C1505="",$S1505="",$S1505=1),"",IFERROR(INDEX($Q$6:$Q$1505,MATCH($C1505&"|"&$A1505&"|"&($S1505-1),$V$6:$V$1505,0)),"")) | X1505: =IF(OR($W1505="",$Q1505="",LEFT($Q1505,1)="—"),"",IF($W1505=$Q1505,"ללא שינוי","מ-"&$W1505&" ל-"&$Q1505))

Sheet דף הכיתה
A1: דף הכיתה — חלוקה לקבוצות הוראה
A2: בוחרים כיתה, שנה ופעימה. הנתונים משני גיליונות ההזנה מתעדכנים אוטומטית. הדף מיועד להדפסה.
A4: הכיתה: | B4: ח1 | C4: שנה: | D4: תשפ"ז | E4: פעימה: | F4: תחילת שנה
A5: =IF($B$4="","",COUNTIFS('הזנה ב-ו'!$B$6:$B$1505,$B$4,'הזנה ב-ו'!$A$6:$A$1505,$D$4,'הזנה ב-ו'!$F$6:$F$1505,$F$4)+COUNTIFS('הזנה רכישה'!$B$6:$B$1505,$B$4,'הזנה רכישה'!$A$6:$A$1505,$D$4,'הזנה רכישה'!$F$6:$F$1505,$F$4)&" תלמידים הוזנו בפעימה זו")
A7: הקבוצה | B7: מספר תלמידים | C7: שיעור מן הכיתה | D7: מוקד העבודה בקבוצה
A8: רמה א' | B8: =IF($B$4="","",COUNTIFS('הזנה ב-ו'!$B$6:$B$1505,$B$4,'הזנה ב-ו'!$A$6:$A$1505,$D$4,'הזנה ב-ו'!$F$6:$F$1505,$F$4,'הזנה ב-ו'!$AC$6:$AC$1505,$A8)) | C8: =IF(OR($B8="",$B$13=0),"",$B8/$B$13) | D8: ביסוס יסודות הקריאה — דיוק, אוטומטיזציה, קריאה חוזרת
A9: רמה ב' | B9: =IF($B$4="","",COUNTIFS('הזנה ב-ו'!$B$6:$B$1505,$B$4,'הזנה ב-ו'!$A$6:$A$1505,$D$4,'הזנה ב-ו'!$F$6:$F$1505,$F$4,'הזנה ב-ו'!$AC$6:$AC$1505,$A9)) | C9: =IF(OR($B9="",$B$13=0),"",$B9/$B$13) | D9: פיתוח שפה והבנה — אוצר מילים, אסטרטגיות הבנה, הבעה
A10: רמה ג' | B10: =IF($B$4="","",COUNTIFS('הזנה ב-ו'!$B$6:$B$1505,$B$4,'הזנה ב-ו'!$A$6:$A$1505,$D$4,'הזנה ב-ו'!$F$6:$F$1505,$F$4,'הזנה ב-ו'!$AC$6:$AC$1505,$A10)) | C10: =IF(OR($B10="",$B$13=0),"",$B10/$B$13) | D10: העמקה — אתגר, עצמאות, שימוש בכישורים ללמידה
A11: קבוצה רביעית: הקניית קריאה | B11: =IF($B$4="","",COUNTIFS('הזנה רכישה'!$B$6:$B$1505,$B$4,'הזנה רכישה'!$A$6:$A$1505,$D$4,'הזנה רכישה'!$F$6:$F$1505,$F$4,'הזנה רכישה'!$R$6:$R$1505,"קבוצה רביעית")) | C11: =IF(OR($B11="",$B$13=0),"",$B11/$B$13) | D11: טרם ביססו את יסודות הקריאה — ראו חלוקה פנימית בהמשך הדף
A12: טרם שויכו | B12: =IF($B$4="","",COUNTIFS('הזנה ב-ו'!$B$6:$B$1505,$B$4,'הזנה ב-ו'!$A$6:$A$1505,$D$4,'הזנה ב-ו'!$F$6:$F$1505,$F$4)+COUNTIFS('הזנה רכישה'!$B$6:$B$1505,$B$4,'הזנה רכישה'!$A$6:$A$1505,$D$4,'הזנה רכישה'!$F$6:$F$1505,$F$4)-SUM($B$8:$B$11)) | C12: =IF(OR($B12="",$B$13=0),"",$B12/$B$13) | D12: חסרים נתונים בגיליון ההזנה — יש להשלים כדי שהתלמיד ישויך לקבוצה
A13: סה"כ | B13: =SUM(B8:B12)
A15: הרכב הקבוצות — תפקוד אורייני ברמת ב'-ו'
A16: רמה א' | B16: דגש נוסף | C16: תנועה מהפעימה הקודמת | D16: רמה ב' | E16: דגש נוסף | F16: תנועה מהפעימה הקודמת | G16: רמה ג' | H16: דגש נוסף | I16: תנועה מהפעימה הקודמת
A17: {=IFERROR(INDEX('הזנה ב-ו'!$C$6:$C$1505,MATCH($B$4&"|"&$D$4&"|"&$F$4&"|רמה א'|"&1,'הזנה ב-ו'!$AF$6:$AF$1505,0)),"")} | B17: {=IFERROR(INDEX('הזנה ב-ו'!$AD$6:$AD$1505,MATCH($B$4&"|"&$D$4&"|"&$F$4&"|רמה א'|"&1,'הזנה ב-ו'!$AF$6:$AF$1505,0)),"")} | C17: {=IFERROR(INDEX('הזנה ב-ו'!$AJ$6:$AJ$1505,MATCH($B$4&"|"&$D$4&"|"&$F$4&"|רמה א'|"&1,'הזנה ב-ו'!$AF$6:$AF$1505,0)),"")} | D17: {=IFERROR(INDEX('הזנה ב-ו'!$C$6:$C$1505,MATCH($B$4&"|"&$D$4&"|"&$F$4&"|רמה ב'|"&1,'הזנה ב-ו'!$AF$6:$AF$1505,0)),"")} | E17: {=IFERROR(INDEX('הזנה ב-ו'!$AD$6:$AD$1505,MATCH($B$4&"|"&$D$4&"|"&$F$4&"|רמה ב'|"&1,'הזנה ב-ו'!$AF$6:$AF$1505,0)),"")} | F17: {=IFERROR(INDEX('הזנה ב-ו'!$AJ$6:$AJ$1505,MATCH($B$4&"|"&$D$4&"|"&$F$4&"|רמה ב'|"&1,'הזנה ב-ו'!$AF$6:$AF$1505,0)),"")} | G17: {=IFERROR(INDEX('הזנה ב-ו'!$C$6:$C$1505,MATCH($B$4&"|"&$D$4&"|"&$F$4&"|רמה ג'|"&1,'הזנה ב-ו'!$AF$6:$AF$1505,0)),"")} | H17: {=IFERROR(INDEX('הזנה ב-ו'!$AD$6:$AD$1505,MATCH($B$4&"|"&$D$4&"|"&$F$4&"|רמה ג'|"&1,'הזנה ב-ו'!$AF$6:$AF$1505,0)),"")} | I17: {=IFERROR(INDEX('הזנה ב-ו'!$AJ$6:$AJ$1505,MATCH($B$4&"|"&$D$4&"|"&$F$4&"|רמה ג'|"&1,'הזנה ב-ו'!$AF$6:$AF$1505,0)),"")}
A18: {=IFERROR(INDEX('הזנה ב-ו'!$C$6:$C$1505,MATCH($B$4&"|"&$D$4&"|"&$F$4&"|רמה א'|"&2,'הזנה ב-ו'!$AF$6:$AF$1505,0)),"")} | B18: {=IFERROR(INDEX('הזנה ב-ו'!$AD$6:$AD$1505,MATCH($B$4&"|"&$D$4&"|"&$F$4&"|רמה א'|"&2,'הזנה ב-ו'!$AF$6:$AF$1505,0)),"")} | C18: {=IFERROR(INDEX('הזנה ב-ו'!$AJ$6:$AJ$1505,MATCH($B$4&"|"&$D$4&"|"&$F$4&"|רמה א'|"&2,'הזנה ב-ו'!$AF$6:$AF$1505,0)),"")} | D18: {=IFERROR(INDEX('הזנה ב-ו'!$C$6:$C$1505,MATCH($B$4&"|"&$D$4&"|"&$F$4&"|רמה ב'|"&2,'הזנה ב-ו'!$AF$6:$AF$1505,0)),"")} | E18: {=IFERROR(INDEX('הזנה ב-ו'!$AD$6:$AD$1505,MATCH($B$4&"|"&$D$4&"|"&$F$4&"|רמה ב'|"&2,'הזנה ב-ו'!$AF$6:$AF$1505,0)),"")} | F18: {=IFERROR(INDEX('הזנה ב-ו'!$AJ$6:$AJ$1505,MATCH($B$4&"|"&$D$4&"|"&$F$4&"|רמה ב'|"&2,'הזנה ב-ו'!$AF$6:$AF$1505,0)),"")} | G18: {=IFERROR(INDEX('הזנה ב-ו'!$C$6:$C$1505,MATCH($B$4&"|"&$D$4&"|"&$F$4&"|רמה ג'|"&2,'הזנה ב-ו'!$AF$6:$AF$1505,0)),"")} | H18: {=IFERROR(INDEX('הזנה ב-ו'!$AD$6:$AD$1505,MATCH($B$4&"|"&$D$4&"|"&$F$4&"|רמה ג'|"&2,'הזנה ב-ו'!$AF$6:$AF$1505,0)),"")} | I18: {=IFERROR(INDEX('הזנה ב-ו'!$AJ$6:$AJ$1505,MATCH($B$4&"|"&$D$4&"|"&$F$4&"|רמה ג'|"&2,'הזנה ב-ו'!$AF$6:$AF$1505,0)),"")}
A19: {=IFERROR(INDEX('הזנה ב-ו'!$C$6:$C$1505,MATCH($B$4&"|"&$D$4&"|"&$F$4&"|רמה א'|"&3,'הזנה ב-ו'!$AF$6:$AF$1505,0)),"")} | B19: {=IFERROR(INDEX('הזנה ב-ו'!$AD$6:$AD$1505,MATCH($B$4&"|"&$D$4&"|"&$F$4&"|רמה א'|"&3,'הזנה ב-ו'!$AF$6:$AF$1505,0)),"")} | C19: {=IFERROR(INDEX('הזנה ב-ו'!$AJ$6:$AJ$1505,MATCH($B$4&"|"&$D$4&"|"&$F$4&"|רמה א'|"&3,'הזנה ב-ו'!$AF$6:$AF$1505,0)),"")} | D19: {=IFERROR(INDEX('הזנה ב-ו'!$C$6:$C$1505,MATCH($B$4&"|"&$D$4&"|"&$F$4&"|רמה ב'|"&3,'הזנה ב-ו'!$AF$6:$AF$1505,0)),"")} | E19: {=IFERROR(INDEX('הזנה ב-ו'!$AD$6:$AD$1505,MATCH($B$4&"|"&$D$4&"|"&$F$4&"|רמה ב'|"&3,'הזנה ב-ו'!$AF$6:$AF$1505,0)),"")} | F19: {=IFERROR(INDEX('הזנה ב-ו'!$AJ$6:$AJ$1505,MATCH($B$4&"|"&$D$4&"|"&$F$4&"|רמה ב'|"&3,'הזנה ב-ו'!$AF$6:$AF$1505,0)),"")} | G19: {=IFERROR(INDEX('הזנה ב-ו'!$C$6:$C$1505,MATCH($B$4&"|"&$D$4&"|"&$F$4&"|רמה ג'|"&3,'הזנה ב-ו'!$AF$6:$AF$1505,0)),"")} | H19: {=IFERROR(INDEX('הזנה ב-ו'!$AD$6:$AD$1505,MATCH($B$4&"|"&$D$4&"|"&$F$4&"|רמה ג'|"&3,'הזנה ב-ו'!$AF$6:$AF$1505,0)),"")} | I19: {=IFERROR(INDEX('הזנה ב-ו'!$AJ$6:$AJ$1505,MATCH($B$4&"|"&$D$4&"|"&$F$4&"|רמה ג'|"&3,'הזנה ב-ו'!$AF$6:$AF$1505,0)),"")}
A20: {=IFERROR(INDEX('הזנה ב-ו'!$C$6:$C$1505,MATCH($B$4&"|"&$D$4&"|"&$F$4&"|רמה א'|"&4,'הזנה ב-ו'!$AF$6:$AF$1505,0)),"")} | B20: {=IFERROR(INDEX('הזנה ב-ו'!$AD$6:$AD$1505,MATCH($B$4&"|"&$D$4&"|"&$F$4&"|רמה א'|"&4,'הזנה ב-ו'!$AF$6:$AF$1505,0)),"")} | C20: {=IFERROR(INDEX('הזנה ב-ו'!$AJ$6:$AJ$1505,MATCH($B$4&"|"&$D$4&"|"&$F$4&"|רמה א'|"&4,'הזנה ב-ו'!$AF$6:$AF$1505,0)),"")} | D20: {=IFERROR(INDEX('הזנה ב-ו'!$C$6:$C$1505,MATCH($B$4&"|"&$D$4&"|"&$F$4&"|רמה ב'|"&4,'הזנה ב-ו'!$AF$6:$AF$1505,0)),"")} | E20: {=IFERROR(INDEX('הזנה ב-ו'!$AD$6:$AD$1505,MATCH($B$4&"|"&$D$4&"|"&$F$4&"|רמה ב'|"&4,'הזנה ב-ו'!$AF$6:$AF$1505,0)),"")} | F20: {=IFERROR(INDEX('הזנה ב-ו'!$AJ$6:$AJ$1505,MATCH($B$4&"|"&$D$4&"|"&$F$4&"|רמה ב'|"&4,'הזנה ב-ו'!$AF$6:$AF$1505,0)),"")} | G20: {=IFERROR(INDEX('הזנה ב-ו'!$C$6:$C$1505,MATCH($B$4&"|"&$D$4&"|"&$F$4&"|רמה ג'|"&4,'הזנה ב-ו'!$AF$6:$AF$1505,0)),"")} | H20: {=IFERROR(INDEX('הזנה ב-ו'!$AD$6:$AD$1505,MATCH($B$4&"|"&$D$4&"|"&$F$4&"|רמה ג'|"&4,'הזנה ב-ו'!$AF$6:$AF$1505,0)),"")} | I20: {=IFERROR(INDEX('הזנה ב-ו'!$AJ$6:$AJ$1505,MATCH($B$4&"|"&$D$4&"|"&$F$4&"|רמה ג'|"&4,'הזנה ב-ו'!$AF$6:$AF$1505,0)),"")}
A21: {=IFERROR(INDEX('הזנה ב-ו'!$C$6:$C$1505,MATCH($B$4&"|"&$D$4&"|"&$F$4&"|רמה א'|"&5,'הזנה ב-ו'!$AF$6:$AF$1505,0)),"")} | B21: {=IFERROR(INDEX('הזנה ב-ו'!$AD$6:$AD$1505,MATCH($B$4&"|"&$D$4&"|"&$F$4&"|רמה א'|"&5,'הזנה ב-ו'!$AF$6:$AF$1505,0)),"")} | C21: {=IFERROR(INDEX('הזנה ב-ו'!$AJ$6:$AJ$1505,MATCH($B$4&"|"&$D$4&"|"&$F$4&"|רמה א'|"&5,'הזנה ב-ו'!$AF$6:$AF$1505,0)),"")} | D21: {=IFERROR(INDEX('הזנה ב-ו'!$C$6:$C$1505,MATCH($B$4&"|"&$D$4&"|"&$F$4&"|רמה ב'|"&5,'הזנה ב-ו'!$AF$6:$AF$1505,0)),"")} | E21: {=IFERROR(INDEX('הזנה ב-ו'!$AD$6:$AD$1505,MATCH($B$4&"|"&$D$4&"|"&$F$4&"|רמה ב'|"&5,'הזנה ב-ו'!$AF$6:$AF$1505,0)),"")} | F21: {=IFERROR(INDEX('הזנה ב-ו'!$AJ$6:$AJ$1505,MATCH($B$4&"|"&$D$4&"|"&$F$4&"|רמה ב'|"&5,'הזנה ב-ו'!$AF$6:$AF$1505,0)),"")} | G21: {=IFERROR(INDEX('הזנה ב-ו'!$C$6:$C$1505,MATCH($B$4&"|"&$D$4&"|"&$F$4&"|רמה ג'|"&5,'הזנה ב-ו'!$AF$6:$AF$1505,0)),"")} | H21: {=IFERROR(INDEX('הזנה ב-ו'!$AD$6:$AD$1505,MATCH($B$4&"|"&$D$4&"|"&$F$4&"|רמה ג'|"&5,'הזנה ב-ו'!$AF$6:$AF$1505,0)),"")} | I21: {=IFERROR(INDEX('הזנה ב-ו'!$AJ$6:$AJ$1505,MATCH($B$4&"|"&$D$4&"|"&$F$4&"|רמה ג'|"&5,'הזנה ב-ו'!$AF$6:$AF$1505,0)),"")}
A22: {=IFERROR(INDEX('הזנה ב-ו'!$C$6:$C$1505,MATCH($B$4&"|"&$D$4&"|"&$F$4&"|רמה א'|"&6,'הזנה ב-ו'!$AF$6:$AF$1505,0)),"")} | B22: {=IFERROR(INDEX('הזנה ב-ו'!$AD$6:$AD$1505,MATCH($B$4&"|"&$D$4&"|"&$F$4&"|רמה א'|"&6,'הזנה ב-ו'!$AF$6:$AF$1505,0)),"")} | C22: {=IFERROR(INDEX('הזנה ב-ו'!$AJ$6:$AJ$1505,MATCH($B$4&"|"&$D$4&"|"&$F$4&"|רמה א'|"&6,'הזנה ב-ו'!$AF$6:$AF$1505,0)),"")} | D22: {=IFERROR(INDEX('הזנה ב-ו'!$C$6:$C$1505,MATCH($B$4&"|"&$D$4&"|"&$F$4&"|רמה ב'|"&6,'הזנה ב-ו'!$AF$6:$AF$1505,0)),"")} | E22: {=IFERROR(INDEX('הזנה ב-ו'!$AD$6:$AD$1505,MATCH($B$4&"|"&$D$4&"|"&$F$4&"|רמה ב'|"&6,'הזנה ב-ו'!$AF$6:$AF$1505,0)),"")} | F22: {=IFERROR(INDEX('הזנה ב-ו'!$AJ$6:$AJ$1505,MATCH($B$4&"|"&$D$4&"|"&$F$4&"|רמה ב'|"&6,'הזנה ב-ו'!$AF$6:$AF$1505,0)),"")} | G22: {=IFERROR(INDEX('הזנה ב-ו'!$C$6:$C$1505,MATCH($B$4&"|"&$D$4&"|"&$F$4&"|רמה ג'|"&6,'הזנה ב-ו'!$AF$6:$AF$1505,0)),"")} | H22: {=IFERROR(INDEX('הזנה ב-ו'!$AD$6:$AD$1505,MATCH($B$4&"|"&$D$4&"|"&$F$4&"|רמה ג'|"&6,'הזנה ב-ו'!$AF$6:$AF$1505,0)),"")} | I22: {=IFERROR(INDEX('הזנה ב-ו'!$AJ$6:$AJ$1505,MATCH($B$4&"|"&$D$4&"|"&$F$4&"|רמה ג'|"&6,'הזנה ב-ו'!$AF$6:$AF$1505,0)),"")}
A23: {=IFERROR(INDEX('הזנה ב-ו'!$C$6:$C$1505,MATCH($B$4&"|"&$D$4&"|"&$F$4&"|רמה א'|"&7,'הזנה ב-ו'!$AF$6:$AF$1505,0)),"")} | B23: {=IFERROR(INDEX('הזנה ב-ו'!$AD$6:$AD$1505,MATCH($B$4&"|"&$D$4&"|"&$F$4&"|רמה א'|"&7,'הזנה ב-ו'!$AF$6:$AF$1505,0)),"")} | C23: {=IFERROR(INDEX('הזנה ב-ו'!$AJ$6:$AJ$1505,MATCH($B$4&"|"&$D$4&"|"&$F$4&"|רמה א'|"&7,'הזנה ב-ו'!$AF$6:$AF$1505,0)),"")} | D23: {=IFERROR(INDEX('הזנה ב-ו'!$C$6:$C$1505,MATCH($B$4&"|"&$D$4&"|"&$F$4&"|רמה ב'|"&7,'הזנה ב-ו'!$AF$6:$AF$1505,0)),"")} | E23: {=IFERROR(INDEX('הזנה ב-ו'!$AD$6:$AD$1505,MATCH($B$4&"|"&$D$4&"|"&$F$4&"|רמה ב'|"&7,'הזנה ב-ו'!$AF$6:$AF$1505,0)),"")} | F23: {=IFERROR(INDEX('הזנה ב-ו'!$AJ$6:$AJ$1505,MATCH($B$4&"|"&$D$4&"|"&$F$4&"|רמה ב'|"&7,'הזנה ב-ו'!$AF$6:$AF$1505,0)),"")} | G23: {=IFERROR(INDEX('הזנה ב-ו'!$C$6:$C$1505,MATCH($B$4&"|"&$D$4&"|"&$F$4&"|רמה ג'|"&7,'הזנה ב-ו'!$AF$6:$AF$1505,0)),"")} | H23: {=IFERROR(INDEX('הזנה ב-ו'!$AD$6:$AD$1505,MATCH($B$4&"|"&$D$4&"|"&$F$4&"|רמה ג'|"&7,'הזנה ב-ו'!$AF$6:$AF$1505,0)),"")} | I23: {=IFERROR(INDEX('הזנה ב-ו'!$AJ$6:$AJ$1505,MATCH($B$4&"|"&$D$4&"|"&$F$4&"|רמה ג'|"&7,'הזנה ב-ו'!$AF$6:$AF$1505,0)),"")}
A24: {=IFERROR(INDEX('הזנה ב-ו'!$C$6:$C$1505,MATCH($B$4&"|"&$D$4&"|"&$F$4&"|רמה א'|"&8,'הזנה ב-ו'!$AF$6:$AF$1505,0)),"")} | B24: {=IFERROR(INDEX('הזנה ב-ו'!$AD$6:$AD$1505,MATCH($B$4&"|"&$D$4&"|"&$F$4&"|רמה א'|"&8,'הזנה ב-ו'!$AF$6:$AF$1505,0)),"")} | C24: {=IFERROR(INDEX('הזנה ב-ו'!$AJ$6:$AJ$1505,MATCH($B$4&"|"&$D$4&"|"&$F$4&"|רמה א'|"&8,'הזנה ב-ו'!$AF$6:$AF$1505,0)),"")} | D24: {=IFERROR(INDEX('הזנה ב-ו'!$C$6:$C$1505,MATCH($B$4&"|"&$D$4&"|"&$F$4&"|רמה ב'|"&8,'הזנה ב-ו'!$AF$6:$AF$1505,0)),"")} | E24: {=IFERROR(INDEX('הזנה ב-ו'!$AD$6:$AD$1505,MATCH($B$4&"|"&$D$4&"|"&$F$4&"|רמה ב'|"&8,'הזנה ב-ו'!$AF$6:$AF$1505,0)),"")} | F24: {=IFERROR(INDEX('הזנה ב-ו'!$AJ$6:$AJ$1505,MATCH($B$4&"|"&$D$4&"|"&$F$4&"|רמה ב'|"&8,'הזנה ב-ו'!$AF$6:$AF$1505,0)),"")} | G24: {=IFERROR(INDEX('הזנה ב-ו'!$C$6:$C$1505,MATCH($B$4&"|"&$D$4&"|"&$F$4&"|רמה ג'|"&8,'הזנה ב-ו'!$AF$6:$AF$1505,0)),"")} | H24: {=IFERROR(INDEX('הזנה ב-ו'!$AD$6:$AD$1505,MATCH($B$4&"|"&$D$4&"|"&$F$4&"|רמה ג'|"&8,'הזנה ב-ו'!$AF$6:$AF$1505,0)),"")} | I24: {=IFERROR(INDEX('הזנה ב-ו'!$AJ$6:$AJ$1505,MATCH($B$4&"|"&$D$4&"|"&$F$4&"|רמה ג'|"&8,'הזנה ב-ו'!$AF$6:$AF$1505,0)),"")}
A25: {=IFERROR(INDEX('הזנה ב-ו'!$C$6:$C$1505,MATCH($B$4&"|"&$D$4&"|"&$F$4&"|רמה א'|"&9,'הזנה ב-ו'!$AF$6:$AF$1505,0)),"")} | B25: {=IFERROR(INDEX('הזנה ב-ו'!$AD$6:$AD$1505,MATCH($B$4&"|"&$D$4&"|"&$F$4&"|רמה א'|"&9,'הזנה ב-ו'!$AF$6:$AF$1505,0)),"")} | C25: {=IFERROR(INDEX('הזנה ב-ו'!$AJ$6:$AJ$1505,MATCH($B$4&"|"&$D$4&"|"&$F$4&"|רמה א'|"&9,'הזנה ב-ו'!$AF$6:$AF$1505,0)),"")} | D25: {=IFERROR(INDEX('הזנה ב-ו'!$C$6:$C$1505,MATCH($B$4&"|"&$D$4&"|"&$F$4&"|רמה ב'|"&9,'הזנה ב-ו'!$AF$6:$AF$1505,0)),"")} | E25: {=IFERROR(INDEX('הזנה ב-ו'!$AD$6:$AD$1505,MATCH($B$4&"|"&$D$4&"|"&$F$4&"|רמה ב'|"&9,'הזנה ב-ו'!$AF$6:$AF$1505,0)),"")} | F25: {=IFERROR(INDEX('הזנה ב-ו'!$AJ$6:$AJ$1505,MATCH($B$4&"|"&$D$4&"|"&$F$4&"|רמה ב'|"&9,'הזנה ב-ו'!$AF$6:$AF$1505,0)),"")} | G25: {=IFERROR(INDEX('הזנה ב-ו'!$C$6:$C$1505,MATCH($B$4&"|"&$D$4&"|"&$F$4&"|רמה ג'|"&9,'הזנה ב-ו'!$AF$6:$AF$1505,0)),"")} | H25: {=IFERROR(INDEX('הזנה ב-ו'!$AD$6:$AD$1505,MATCH($B$4&"|"&$D$4&"|"&$F$4&"|רמה ג'|"&9,'הזנה ב-ו'!$AF$6:$AF$1505,0)),"")} | I25: {=IFERROR(INDEX('הזנה ב-ו'!$AJ$6:$AJ$1505,MATCH($B$4&"|"&$D$4&"|"&$F$4&"|רמה ג'|"&9,'הזנה ב-ו'!$AF$6:$AF$1505,0)),"")}
A26: {=IFERROR(INDEX('הזנה ב-ו'!$C$6:$C$1505,MATCH($B$4&"|"&$D$4&"|"&$F$4&"|רמה א'|"&10,'הזנה ב-ו'!$AF$6:$AF$1505,0)),"")} | B26: {=IFERROR(INDEX('הזנה ב-ו'!$AD$6:$AD$1505,MATCH($B$4&"|"&$D$4&"|"&$F$4&"|רמה א'|"&10,'הזנה ב-ו'!$AF$6:$AF$1505,0)),"")} | C26: {=IFERROR(INDEX('הזנה ב-ו'!$AJ$6:$AJ$1505,MATCH($B$4&"|"&$D$4&"|"&$F$4&"|רמה א'|"&10,'הזנה ב-ו'!$AF$6:$AF$1505,0)),"")} | D26: {=IFERROR(INDEX('הזנה ב-ו'!$C$6:$C$1505,MATCH($B$4&"|"&$D$4&"|"&$F$4&"|רמה ב'|"&10,'הזנה ב-ו'!$AF$6:$AF$1505,0)),"")} | E26: {=IFERROR(INDEX('הזנה ב-ו'!$AD$6:$AD$1505,MATCH($B$4&"|"&$D$4&"|"&$F$4&"|רמה ב'|"&10,'הזנה ב-ו'!$AF$6:$AF$1505,0)),"")} | F26: {=IFERROR(INDEX('הזנה ב-ו'!$AJ$6:$AJ$1505,MATCH($B$4&"|"&$D$4&"|"&$F$4&"|רמה ב'|"&10,'הזנה ב-ו'!$AF$6:$AF$1505,0)),"")} | G26: {=IFERROR(INDEX('הזנה ב-ו'!$C$6:$C$1505,MATCH($B$4&"|"&$D$4&"|"&$F$4&"|רמה ג'|"&10,'הזנה ב-ו'!$AF$6:$AF$1505,0)),"")} | H26: {=IFERROR(INDEX('הזנה ב-ו'!$AD$6:$AD$1505,MATCH($B$4&"|"&$D$4&"|"&$F$4&"|רמה ג'|"&10,'הזנה ב-ו'!$AF$6:$AF$1505,0)),"")} | I26: {=IFERROR(INDEX('הזנה ב-ו'!$AJ$6:$AJ$1505,MATCH($B$4&"|"&$D$4&"|"&$F$4&"|רמה ג'|"&10,'הזנה ב-ו'!$AF$6:$AF$1505,0)),"")}
A27: {=IFERROR(INDEX('הזנה ב-ו'!$C$6:$C$1505,MATCH($B$4&"|"&$D$4&"|"&$F$4&"|רמה א'|"&11,'הזנה ב-ו'!$AF$6:$AF$1505,0)),"")} | B27: {=IFERROR(INDEX('הזנה ב-ו'!$AD$6:$AD$1505,MATCH($B$4&"|"&$D$4&"|"&$F$4&"|רמה א'|"&11,'הזנה ב-ו'!$AF$6:$AF$1505,0)),"")} | C27: {=IFERROR(INDEX('הזנה ב-ו'!$AJ$6:$AJ$1505,MATCH($B$4&"|"&$D$4&"|"&$F$4&"|רמה א'|"&11,'הזנה ב-ו'!$AF$6:$AF$1505,0)),"")} | D27: {=IFERROR(INDEX('הזנה ב-ו'!$C$6:$C$1505,MATCH($B$4&"|"&$D$4&"|"&$F$4&"|רמה ב'|"&11,'הזנה ב-ו'!$AF$6:$AF$1505,0)),"")} | E27: {=IFERROR(INDEX('הזנה ב-ו'!$AD$6:$AD$1505,MATCH($B$4&"|"&$D$4&"|"&$F$4&"|רמה ב'|"&11,'הזנה ב-ו'!$AF$6:$AF$1505,0)),"")} | F27: {=IFERROR(INDEX('הזנה ב-ו'!$AJ$6:$AJ$1505,MATCH($B$4&"|"&$D$4&"|"&$F$4&"|רמה ב'|"&11,'הזנה ב-ו'!$AF$6:$AF$1505,0)),"")} | G27: {=IFERROR(INDEX('הזנה ב-ו'!$C$6:$C$1505,MATCH($B$4&"|"&$D$4&"|"&$F$4&"|רמה ג'|"&11,'הזנה ב-ו'!$AF$6:$AF$1505,0)),"")} | H27: {=IFERROR(INDEX('הזנה ב-ו'!$AD$6:$AD$1505,MATCH($B$4&"|"&$D$4&"|"&$F$4&"|רמה ג'|"&11,'הזנה ב-ו'!$AF$6:$AF$1505,0)),"")} | I27: {=IFERROR(INDEX('הזנה ב-ו'!$AJ$6:$AJ$1505,MATCH($B$4&"|"&$D$4&"|"&$F$4&"|רמה ג'|"&11,'הזנה ב-ו'!$AF$6:$AF$1505,0)),"")}
A28: {=IFERROR(INDEX('הזנה ב-ו'!$C$6:$C$1505,MATCH($B$4&"|"&$D$4&"|"&$F$4&"|רמה א'|"&12,'הזנה ב-ו'!$AF$6:$AF$1505,0)),"")} | B28: {=IFERROR(INDEX('הזנה ב-ו'!$AD$6:$AD$1505,MATCH($B$4&"|"&$D$4&"|"&$F$4&"|רמה א'|"&12,'הזנה ב-ו'!$AF$6:$AF$1505,0)),"")} | C28: {=IFERROR(INDEX('הזנה ב-ו'!$AJ$6:$AJ$1505,MATCH($B$4&"|"&$D$4&"|"&$F$4&"|רמה א'|"&12,'הזנה ב-ו'!$AF$6:$AF$1505,0)),"")} | D28: {=IFERROR(INDEX('הזנה ב-ו'!$C$6:$C$1505,MATCH($B$4&"|"&$D$4&"|"&$F$4&"|רמה ב'|"&12,'הזנה ב-ו'!$AF$6:$AF$1505,0)),"")} | E28: {=IFERROR(INDEX('הזנה ב-ו'!$AD$6:$AD$1505,MATCH($B$4&"|"&$D$4&"|"&$F$4&"|רמה ב'|"&12,'הזנה ב-ו'!$AF$6:$AF$1505,0)),"")} | F28: {=IFERROR(INDEX('הזנה ב-ו'!$AJ$6:$AJ$1505,MATCH($B$4&"|"&$D$4&"|"&$F$4&"|רמה ב'|"&12,'הזנה ב-ו'!$AF$6:$AF$1505,0)),"")} | G28: {=IFERROR(INDEX('הזנה ב-ו'!$C$6:$C$1505,MATCH($B$4&"|"&$D$4&"|"&$F$4&"|רמה ג'|"&12,'הזנה ב-ו'!$AF$6:$AF$1505,0)),"")} | H28: {=IFERROR(INDEX('הזנה ב-ו'!$AD$6:$AD$1505,MATCH($B$4&"|"&$D$4&"|"&$F$4&"|רמה ג'|"&12,'הזנה ב-ו'!$AF$6:$AF$1505,0)),"")} | I28: {=IFERROR(INDEX('הזנה ב-ו'!$AJ$6:$AJ$1505,MATCH($B$4&"|"&$D$4&"|"&$F$4&"|רמה ג'|"&12,'הזנה ב-ו'!$AF$6:$AF$1505,0)),"")}
A30: הרכב הקבוצות — קבוצה רביעית: הקניית קריאה
A31: קבוצה רביעית | B31: הפרופיל | C31: תנועה מהפעימה הקודמת | D31: קבוצת רכישה | E31: הפרופיל | F31: תנועה מהפעימה הקודמת | G31: קבוצת ביסוס | H31: הפרופיל | I31: תנועה מהפעימה הקודמת
